Workbook

Sheet AVE WEEKLY COUNTS AT GLANCE
C2: Friday | D2: Saturday | E2: Sunday | F2: Monday | G2: Tuesday | H2: Wednesday | I2: Thursday | J2: Date
B3: Breakfast | J3: 9/10-9/16
J4: 9/17-9/23
J5: 9/24-9/30
J6: 10/1-10/7
J7: 10/8-10/14
J8: 10/15-10/21
J9: 10/22-10/28
J10: 10/29-11/4
J11: 11/5-11/11
J12: 11/12-11/18
J13: 11/19-11/25
J14: 11/26-12/2
J15: 12/3-12/9
B16: Average | C16: =AVERAGE(C3:C15) -> #DIV/0! | D16: =AVERAGE(D3:D15) -> #DIV/0! | G16: =AVERAGE(G3:G15) -> #DIV/0! | H16: =AVERAGE(H3:H15) -> #DIV/0! | I16: =AVERAGE(I3:I15) -> #DIV/0!
B19: Lunch | J19: 9/10-9/16
J20: 9/17-9/23
J21: 9/24-9/30
J22: 10/1-10/7
J23: 10/8-10/14
J24: 10/15-10/21
J25: 10/22-10/28
J26: 10/29-11/4
J27: 11/5-11/11
J28: 11/12-11/18
J29: 11/19-11/25
J30: 11/26-12/2
J31: 12/3-12/9
B32: Average | C32: =AVERAGE(C19:C31) -> #DIV/0! | D32: =AVERAGE(D19:D31) -> #DIV/0! | E32: =AVERAGE(E19:E31) -> #DIV/0! | F32: =AVERAGE(F19:F31) -> #DIV/0! | G32: =AVERAGE(G19:G31) -> #DIV/0! | H32: =AVERAGE(H19:H31) -> #DIV/0! | I32: =AVERAGE(I19:I31) -> #DIV/0!
B35: Dinner | J35: 9/10-9/16
J36: 9/17-9/23
J37: 9/24-9/30
J38: 10/1-10/7
J39: 10/8-10/14
J40: 10/15-10/21
J41: 10/22-10/28
J42: 10/29-11/4
J43: 11/5-11/11
J44: 11/12-11/18
J45: 11/19-11/25
...

Sheet AUGUST WK 1
E1: Menu Cycle: | G1: Week:
B2: Fri | C2: Sat | D2: Sun | E2: Mon | F2: Tues | G2: Wed | H2: Thu
A3: Date | B3: 45865 | C3: =B3+1 -> 45866 | D3: =C3+1 -> 45867 | E3: =D3+1 -> 45868 | F3: =E3+1 -> 45869 | G3: =F3+1 -> 45870 | H3: =G3+1 -> 45871
A4: Prior Year Actual - 2024
A5: Breakfast
A6: Lunch
A7: Dinner
A8: Total Day | B8: =B5+B6+B7 -> 0 | C8: =C5+C6+C7 -> 0 | D8: =D5+D6+D7 -> 0 | E8: =E5+E6+E7 -> 0 | F8: =F5+F6+F7 -> 0 | G8: =G5+G6+G7 -> 0 | H8: =H5+H6+H7 -> 0
G9: Week Total | H9: =SUM(B8:H8) -> 0
A10: Forecast - 2025 | G10: % Forecast Adj | H10: -0.08
A11: Breakfast
A12: Lunch
A13: Dinner
A14: Total Day | B14: =SUM(B11:B13) -> 0 | C14: =SUM(C11:C13) -> 0 | D14: =SUM(D11:D13) -> 0 | E14: =SUM(E11:E13) -> 0 | F14: =SUM(F11:F13) -> 0 | G14: =SUM(G11:G13) -> 0 | H14: =SUM(H11:H13) -> 0
A15: % vPY Act | B15: =(B14-B8)/B8 -> #DIV/0! | C15: =(C14-C8)/C8 -> #DIV/0! | D15: =(D14-D8)/D8 -> #DIV/0! | E15: =(E14-E8)/E8 -> #DIV/0! | F15: =(F14-F8)/F8 -> #DIV/0! | G15: =(G14-G8)/G8 -> #DIV/0! | H15: =(H14-H8)/H8 -> #DIV/0!
G16: Week Total | H16: =SUM(B14:H14) -> 0
A17: Breakfast | G17: % vPY | H17: =(H16-H9)/H9 -> #DIV/0!
A18: Greeter Total
A19: ='OPENING WEEK 1'!A19 -> Non Meal Plan Meals
A20: Student Meals
A21: Total - Breakfast | B21: =SUM(B18:B20) -> 0 | C21: =SUM(C18:C20) -> 0 | D21: =SUM(D18:D20) -> 0 | E21: =SUM(E18:E20) -> 0 | F21: =SUM(F18:F20) -> 0 | G21: =SUM(G18:G20) -> 0 | H21: =SUM(H18:H20) -> 0
A22: % vPY Act | B22: =(B21-B5)/B5 -> #DIV/0! | C22: =(C21-C5)/C5 -> #DIV/0! | F22: =(F21-F5)/F5 -> #DIV/0! | G22: =(G21-G5)/G5 -> #DIV/0! | H22: =(H21-H5)/H5 -> #DIV/0!
A23: Lunch/Brunch | F23: Brunch/Lunch
A24: Greeter Total
A25: Fulltime Meals
A26: Student Meals
A27: Total - Lunch | B27: =SUM(B24:B26) -> 0 | C27: =C24+C25+C26 -> 0 | D27: =D24+D25+D26 -> 0 | E27: =E24+E25+E26 -> 0 | F27: =F24+F25+F26 -> 0 | G27: =G24+G25+G26 -> 0 | H27: =H24+H25+H26 -> 0
A28: % vPY Act | B28: =(B27-B6)/B6 -> #DIV/0! | C28: =(C27-C6)/C6 -> #DIV/0! | D28: =(D27-D6)/D6 -> #DIV/0! | E28: =(E27-E6)/E6 -> #DIV/0! | F28: =(F27-F6)/F6 -> #DIV/0! | G28: =(G27-G6)/G6 -> #DIV/0! | H28: =(H27-H6)/H6 -> #DIV/0!
A29: Dinner | F29: Dinner
A30: Greeter Total
A31: Fulltime Meals
A32: Student Meals
A33: Total - Dinner | B33: =SUM(B30:B32) -> 0 | C33: =SUM(C30:C32) -> 0 | D33: =SUM(D30:D32) -> 0 | E33: =SUM(E30:E32) -> 0 | F33: =SUM(F30:F32) -> 0 | G33: =SUM(G30:G32) -> 0 | H33: =SUM(H30:H32) -> 0
A34: % vPY Act | B34: =(B33-B7)/B7 -> #DIV/0! | C34: =(C33-C7)/C7 -> #DIV/0! | D34: =(D33-D7)/D7 -> #DIV/0! | E34: =(E33-E7)/E7 -> #DIV/0! | F34: =(F33-F7)/F7 -> #DIV/0! | G34: =(G33-G7)/G7 -> #DIV/0! | H34: =(H33-H7)/H7 -> #DIV/0!
A35: All Day | F35: Dinner
A36: Total - Day | B36: =B33+B27+B21 -> 0 | C36: =C33+C27+C21 -> 0 | D36: =D33+D27+D21 -> 0 | E36: =E33+E27+E21 -> 0 | F36: =F33+F27+F21 -> 0 | G36: =G33+G27+G21 -> 0 | H36: =H33+H27+H21 -> 0
A37: % vPY Act | B37: =(B36-B8)/B8 -> #DIV/0! | C37: =(C36-C8)/C8 -> #DIV/0! | D37: =(D36-D8)/D8 -> #DIV/0! | E37: =(E36-E8)/E8 -> #DIV/0! | F37: =(F36-F8)/F8 -> #DIV/0! | G37: =(G36-G8)/G8 -> #DIV/0! | H37: =(H36-H8)/H8 -> #DIV/0!
G38: Week Total | H38: =SUM(B36:H36) -> 0
G39: % vPY Act | H39: =(H38-H9)/H9 -> #DIV/0!
G40: % vForecast | H40: =(H38-H16)/H16 -> #DIV/0!
...

Sheet AUGUST WK 2
E1: Menu Cycle: | G1: Week:
B2: Fri | C2: Sat | D2: Sun | E2: Mon | F2: Tues | G2: Wed | H2: Thu
A3: Date | B3: 45872 | C3: =B3+1 -> 45873 | D3: =C3+1 -> 45874 | E3: =D3+1 -> 45875 | F3: =E3+1 -> 45876 | G3: =F3+1 -> 45877 | H3: =G3+1 -> 45878
A4: Prior Year Actual - 2024
A5: Breakfast
A6: Lunch
A7: Dinner
A8: Total Day | B8: =B5+B6+B7 -> 0 | C8: =C5+C6+C7 -> 0 | D8: =D5+D6+D7 -> 0 | E8: =E5+E6+E7 -> 0 | F8: =F5+F6+F7 -> 0 | G8: =G5+G6+G7 -> 0 | H8: =H5+H6+H7 -> 0
G9: Week Total | H9: =SUM(B8:H8) -> 0
A10: Forecast - 2025 | G10: % Forecast Adj | H10: -0.08
A11: Breakfast
A12: Lunch
A13: Dinner
A14: Total Day | B14: =SUM(B11:B13) -> 0 | C14: =SUM(C11:C13) -> 0 | D14: =SUM(D11:D13) -> 0 | E14: =SUM(E11:E13) -> 0 | F14: =SUM(F11:F13) -> 0 | G14: =SUM(G11:G13) -> 0 | H14: =SUM(H11:H13) -> 0
A15: % vPY Act | B15: =(B14-B8)/B8 -> #DIV/0! | C15: =(C14-C8)/C8 -> #DIV/0! | D15: =(D14-D8)/D8 -> #DIV/0! | E15: =(E14-E8)/E8 -> #DIV/0! | F15: =(F14-F8)/F8 -> #DIV/0! | G15: =(G14-G8)/G8 -> #DIV/0! | H15: =(H14-H8)/H8 -> #DIV/0!
G16: Week Total | H16: =SUM(B14:H14) -> 0
A17: Breakfast | G17: % vPY | H17: =(H16-H9)/H9 -> #DIV/0!
A18: Greeter Total
A19: ='OPENING WEEK 1'!A19 -> Non Meal Plan Meals
A20: Student Meals
A21: Total - Breakfast | B21: =SUM(B18:B20) -> 0 | C21: =SUM(C18:C20) -> 0 | D21: =SUM(D18:D20) -> 0 | E21: =SUM(E18:E20) -> 0 | F21: =SUM(F18:F20) -> 0 | G21: =SUM(G18:G20) -> 0 | H21: =SUM(H18:H20) -> 0
A22: % vPY Act | B22: =(B21-B5)/B5 -> #DIV/0! | C22: =(C21-C5)/C5 -> #DIV/0! | F22: =(F21-F5)/F5 -> #DIV/0! | G22: =(G21-G5)/G5 -> #DIV/0! | H22: =(H21-H5)/H5 -> #DIV/0!
A23: Lunch/Brunch | F23: Brunch/Lunch
A24: Greeter Total
A25: Fulltime Meals
A26: Student Meals
A27: Total - Lunch | B27: =SUM(B24:B26) -> 0 | C27: =C24+C25+C26 -> 0 | D27: =D24+D25+D26 -> 0 | E27: =E24+E25+E26 -> 0 | F27: =F24+F25+F26 -> 0 | G27: =G24+G25+G26 -> 0 | H27: =H24+H25+H26 -> 0
A28: % vPY Act | B28: =(B27-B6)/B6 -> #DIV/0! | C28: =(C27-C6)/C6 -> #DIV/0! | D28: =(D27-D6)/D6 -> #DIV/0! | E28: =(E27-E6)/E6 -> #DIV/0! | F28: =(F27-F6)/F6 -> #DIV/0! | G28: =(G27-G6)/G6 -> #DIV/0! | H28: =(H27-H6)/H6 -> #DIV/0!
A29: Dinner | F29: Dinner
A30: Greeter Total
A31: Fulltime Meals
A32: Student Meals
A33: Total - Dinner | B33: =SUM(B30:B32) -> 0 | C33: =SUM(C30:C32) -> 0 | D33: =SUM(D30:D32) -> 0 | E33: =SUM(E30:E32) -> 0 | F33: =SUM(F30:F32) -> 0 | G33: =SUM(G30:G32) -> 0 | H33: =SUM(H30:H32) -> 0
A34: % vPY Act | B34: =(B33-B7)/B7 -> #DIV/0! | C34: =(C33-C7)/C7 -> #DIV/0! | D34: =(D33-D7)/D7 -> #DIV/0! | E34: =(E33-E7)/E7 -> #DIV/0! | F34: =(F33-F7)/F7 -> #DIV/0! | G34: =(G33-G7)/G7 -> #DIV/0! | H34: =(H33-H7)/H7 -> #DIV/0!
A35: All Day | F35: Dinner
A36: Total - Day | B36: =B33+B27+B21 -> 0 | C36: =C33+C27+C21 -> 0 | D36: =D33+D27+D21 -> 0 | E36: =E33+E27+E21 -> 0 | F36: =F33+F27+F21 -> 0 | G36: =G33+G27+G21 -> 0 | H36: =H33+H27+H21 -> 0
A37: % vPY Act | B37: =(B36-B8)/B8 -> #DIV/0! | C37: =(C36-C8)/C8 -> #DIV/0! | D37: =(D36-D8)/D8 -> #DIV/0! | E37: =(E36-E8)/E8 -> #DIV/0! | F37: =(F36-F8)/F8 -> #DIV/0! | G37: =(G36-G8)/G8 -> #DIV/0! | H37: =(H36-H8)/H8 -> #DIV/0!
G38: Week Total | H38: =SUM(B36:H36) -> 0
G39: % vPY Act | H39: =(H38-H9)/H9 -> #DIV/0!
G40: % vForecast | H40: =(H38-H16)/H16 -> #DIV/0!
...

Sheet AUGUST WK 3
E1: Menu Cycle: | G1: Week:
B2: Fri | C2: Sat | D2: Sun | E2: Mon | F2: Tues | G2: Wed | H2: Thu
A3: Date | B3: 45879 | C3: =B3+1 -> 45880 | D3: =C3+1 -> 45881 | E3: =D3+1 -> 45882 | F3: =E3+1 -> 45883 | G3: =F3+1 -> 45884 | H3: =G3+1 -> 45885
A4: Prior Year Actual - 2024
A5: Breakfast
A6: Lunch
A7: Dinner
A8: Total Day | B8: =B5+B6+B7 -> 0 | C8: =C5+C6+C7 -> 0 | D8: =D5+D6+D7 -> 0 | E8: =E5+E6+E7 -> 0 | F8: =F5+F6+F7 -> 0 | G8: =G5+G6+G7 -> 0 | H8: =H5+H6+H7 -> 0
G9: Week Total | H9: =SUM(B8:H8) -> 0
A10: Forecast - 2025 | G10: % Forecast Adj | H10: -0.08
A11: Breakfast
A12: Lunch
A13: Dinner
A14: Total Day | B14: =SUM(B11:B13) -> 0 | C14: =SUM(C11:C13) -> 0 | D14: =SUM(D11:D13) -> 0 | E14: =SUM(E11:E13) -> 0 | F14: =SUM(F11:F13) -> 0 | G14: =SUM(G11:G13) -> 0 | H14: =SUM(H11:H13) -> 0
A15: % vPY Act | B15: =(B14-B8)/B8 -> #DIV/0! | C15: =(C14-C8)/C8 -> #DIV/0! | D15: =(D14-D8)/D8 -> #DIV/0! | E15: =(E14-E8)/E8 -> #DIV/0! | F15: =(F14-F8)/F8 -> #DIV/0! | G15: =(G14-G8)/G8 -> #DIV/0! | H15: =(H14-H8)/H8 -> #DIV/0!
G16: Week Total | H16: =SUM(B14:H14) -> 0
A17: Breakfast | G17: % vPY | H17: =(H16-H9)/H9 -> #DIV/0!
A18: Greeter Total
A19: ='OPENING WEEK 1'!A19 -> Non Meal Plan Meals
A20: Student Meals
A21: Total - Breakfast | B21: =SUM(B18:B20) -> 0 | C21: =SUM(C18:C20) -> 0 | D21: =SUM(D18:D20) -> 0 | E21: =SUM(E18:E20) -> 0 | F21: =SUM(F18:F20) -> 0 | G21: =SUM(G18:G20) -> 0 | H21: =SUM(H18:H20) -> 0
A22: % vPY Act | B22: =(B21-B5)/B5 -> #DIV/0! | C22: =(C21-C5)/C5 -> #DIV/0! | F22: =(F21-F5)/F5 -> #DIV/0! | G22: =(G21-G5)/G5 -> #DIV/0! | H22: =(H21-H5)/H5 -> #DIV/0!
A23: Lunch/Brunch | F23: Brunch/Lunch
A24: Greeter Total
A25: Fulltime Meals
A26: Student Meals
A27: Total - Lunch | B27: =SUM(B24:B26) -> 0 | C27: =C24+C25+C26 -> 0 | D27: =D24+D25+D26 -> 0 | E27: =E24+E25+E26 -> 0 | F27: =F24+F25+F26 -> 0 | G27: =G24+G25+G26 -> 0 | H27: =H24+H25+H26 -> 0
A28: % vPY Act | B28: =(B27-B6)/B6 -> #DIV/0! | C28: =(C27-C6)/C6 -> #DIV/0! | D28: =(D27-D6)/D6 -> #DIV/0! | E28: =(E27-E6)/E6 -> #DIV/0! | F28: =(F27-F6)/F6 -> #DIV/0! | G28: =(G27-G6)/G6 -> #DIV/0! | H28: =(H27-H6)/H6 -> #DIV/0!
A29: Dinner | F29: Dinner
A30: Greeter Total
A31: Fulltime Meals
A32: Student Meals
A33: Total - Dinner | B33: =SUM(B30:B32) -> 0 | C33: =SUM(C30:C32) -> 0 | D33: =SUM(D30:D32) -> 0 | E33: =SUM(E30:E32) -> 0 | F33: =SUM(F30:F32) -> 0 | G33: =SUM(G30:G32) -> 0 | H33: =SUM(H30:H32) -> 0
A34: % vPY Act | B34: =(B33-B7)/B7 -> #DIV/0! | C34: =(C33-C7)/C7 -> #DIV/0! | D34: =(D33-D7)/D7 -> #DIV/0! | E34: =(E33-E7)/E7 -> #DIV/0! | F34: =(F33-F7)/F7 -> #DIV/0! | G34: =(G33-G7)/G7 -> #DIV/0! | H34: =(H33-H7)/H7 -> #DIV/0!
A35: All Day | F35: Dinner
A36: Total - Day | B36: =B33+B27+B21 -> 0 | C36: =C33+C27+C21 -> 0 | D36: =D33+D27+D21 -> 0 | E36: =E33+E27+E21 -> 0 | F36: =F33+F27+F21 -> 0 | G36: =G33+G27+G21 -> 0 | H36: =H33+H27+H21 -> 0
A37: % vPY Act | B37: =(B36-B8)/B8 -> #DIV/0! | C37: =(C36-C8)/C8 -> #DIV/0! | D37: =(D36-D8)/D8 -> #DIV/0! | E37: =(E36-E8)/E8 -> #DIV/0! | F37: =(F36-F8)/F8 -> #DIV/0! | G37: =(G36-G8)/G8 -> #DIV/0! | H37: =(H36-H8)/H8 -> #DIV/0!
G38: Week Total | H38: =SUM(B36:H36) -> 0
G39: % vPY Act | H39: =(H38-H9)/H9 -> #DIV/0!
G40: % vForecast | H40: =(H38-H16)/H16 -> #DIV/0!
...

Sheet AUGUST WK 4
E1: Menu Cycle: | G1: Week:
B2: Fri | C2: Sat | D2: Sun | E2: Mon | F2: Tues | G2: Wed | H2: Thu
A3: Date | B3: 45886 | C3: =B3+1 -> 45887 | D3: =C3+1 -> 45888 | E3: =D3+1 -> 45889 | F3: =E3+1 -> 45890 | G3: =F3+1 -> 45891 | H3: =G3+1 -> 45892
A4: Prior Year Actual - 2024
A5: Breakfast
A6: Lunch
A7: Dinner
A8: Total Day | B8: =B5+B6+B7 -> 0 | C8: =C5+C6+C7 -> 0 | D8: =D5+D6+D7 -> 0 | E8: =E5+E6+E7 -> 0 | F8: =F5+F6+F7 -> 0 | G8: =G5+G6+G7 -> 0 | H8: =H5+H6+H7 -> 0
G9: Week Total | H9: =SUM(B8:H8) -> 0
A10: Forecast - 2025 | G10: % Forecast Adj | H10: -0.08
A11: Breakfast
A12: Lunch
A13: Dinner
A14: Total Day | B14: =SUM(B11:B13) -> 0 | C14: =SUM(C11:C13) -> 0 | D14: =SUM(D11:D13) -> 0 | E14: =SUM(E11:E13) -> 0 | F14: =SUM(F11:F13) -> 0 | G14: =SUM(G11:G13) -> 0 | H14: =SUM(H11:H13) -> 0
A15: % vPY Act | B15: =(B14-B8)/B8 -> #DIV/0! | C15: =(C14-C8)/C8 -> #DIV/0! | D15: =(D14-D8)/D8 -> #DIV/0! | E15: =(E14-E8)/E8 -> #DIV/0! | F15: =(F14-F8)/F8 -> #DIV/0! | G15: =(G14-G8)/G8 -> #DIV/0! | H15: =(H14-H8)/H8 -> #DIV/0!
G16: Week Total | H16: =SUM(B14:H14) -> 0
A17: Breakfast | G17: % vPY | H17: =(H16-H9)/H9 -> #DIV/0!
A18: Greeter Total
A19: ='OPENING WEEK 1'!A19 -> Non Meal Plan Meals
A20: Student Meals
A21: Total - Breakfast | B21: =SUM(B18:B20) -> 0 | C21: =SUM(C18:C20) -> 0 | D21: =SUM(D18:D20) -> 0 | E21: =SUM(E18:E20) -> 0 | F21: =SUM(F18:F20) -> 0 | G21: =SUM(G18:G20) -> 0 | H21: =SUM(H18:H20) -> 0
A22: % vPY Act | B22: =(B21-B5)/B5 -> #DIV/0! | C22: =(C21-C5)/C5 -> #DIV/0! | F22: =(F21-F5)/F5 -> #DIV/0! | G22: =(G21-G5)/G5 -> #DIV/0! | H22: =(H21-H5)/H5 -> #DIV/0!
A23: Lunch/Brunch | F23: Brunch/Lunch
A24: Greeter Total
A25: Fulltime Meals
A26: Student Meals
A27: Total - Lunch | B27: =SUM(B24:B26) -> 0 | C27: =C24+C25+C26 -> 0 | D27: =D24+D25+D26 -> 0 | E27: =E24+E25+E26 -> 0 | F27: =F24+F25+F26 -> 0 | G27: =G24+G25+G26 -> 0 | H27: =H24+H25+H26 -> 0
A28: % vPY Act | B28: =(B27-B6)/B6 -> #DIV/0! | C28: =(C27-C6)/C6 -> #DIV/0! | D28: =(D27-D6)/D6 -> #DIV/0! | E28: =(E27-E6)/E6 -> #DIV/0! | F28: =(F27-F6)/F6 -> #DIV/0! | G28: =(G27-G6)/G6 -> #DIV/0! | H28: =(H27-H6)/H6 -> #DIV/0!
A29: Dinner | F29: Dinner
A30: Greeter Total
A31: Fulltime Meals
A32: Student Meals
A33: Total - Dinner | B33: =SUM(B30:B32) -> 0 | C33: =SUM(C30:C32) -> 0 | D33: =SUM(D30:D32) -> 0 | E33: =SUM(E30:E32) -> 0 | F33: =SUM(F30:F32) -> 0 | G33: =SUM(G30:G32) -> 0 | H33: =SUM(H30:H32) -> 0
A34: % vPY Act | B34: =(B33-B7)/B7 -> #DIV/0! | C34: =(C33-C7)/C7 -> #DIV/0! | D34: =(D33-D7)/D7 -> #DIV/0! | E34: =(E33-E7)/E7 -> #DIV/0! | F34: =(F33-F7)/F7 -> #DIV/0! | G34: =(G33-G7)/G7 -> #DIV/0! | H34: =(H33-H7)/H7 -> #DIV/0!
A35: All Day | F35: Dinner
A36: Total - Day | B36: =B33+B27+B21 -> 0 | C36: =C33+C27+C21 -> 0 | D36: =D33+D27+D21 -> 0 | E36: =E33+E27+E21 -> 0 | F36: =F33+F27+F21 -> 0 | G36: =G33+G27+G21 -> 0 | H36: =H33+H27+H21 -> 0
A37: % vPY Act | B37: =(B36-B8)/B8 -> #DIV/0! | C37: =(C36-C8)/C8 -> #DIV/0! | D37: =(D36-D8)/D8 -> #DIV/0! | E37: =(E36-E8)/E8 -> #DIV/0! | F37: =(F36-F8)/F8 -> #DIV/0! | G37: =(G36-G8)/G8 -> #DIV/0! | H37: =(H36-H8)/H8 -> #DIV/0!
G38: Week Total | H38: =SUM(B36:H36) -> 0
G39: % vPY Act | H39: =(H38-H9)/H9 -> #DIV/0!
G40: % vForecast | H40: =(H38-H16)/H16 -> #DIV/0!
...

Sheet OPENING WEEK 1
E1: Menu Cycle: | G1: Week:
B2: Sun | C2: Mon | D2: Tues | E2: Wed | F2: Thu | G2: Fri | H2: Sat
A3: Date | B3: ='AUGUST WK 4'!H3+1 -> 45893 | C3: =B3+1 -> 45894 | D3: =C3+1 -> 45895 | E3: =D3+1 -> 45896 | F3: =E3+1 -> 45897 | G3: =F3+1 -> 45898 | H3: =G3+1 -> 45899
A4: Prior Year Actual - 2024
A5: Breakfast
A6: Lunch
A7: Dinner
A8: Total Day | B8: =B5+B6+B7 -> 0 | C8: =C5+C6+C7 -> 0 | D8: =D5+D6+D7 -> 0 | E8: =E5+E6+E7 -> 0 | F8: =F5+F6+F7 -> 0 | G8: =G5+G6+G7 -> 0 | H8: =H5+H6+H7 -> 0
G9: Week Total | H9: =SUM(B8:H8) -> 0
A10: Forecast - 2025 | G10: % Forecast Adj | H10: -0.08
A11: Breakfast
A12: Lunch
A13: Dinner
A14: Total Day | B14: =SUM(B11:B13) -> 0 | C14: =SUM(C11:C13) -> 0 | D14: =SUM(D11:D13) -> 0 | E14: =SUM(E11:E13) -> 0 | F14: =SUM(F11:F13) -> 0 | G14: =SUM(G11:G13) -> 0 | H14: =SUM(H11:H13) -> 0
A15: % vPY Act | B15: =(B14-B8)/B8 -> #DIV/0! | C15: =(C14-C8)/C8 -> #DIV/0! | D15: =(D14-D8)/D8 -> #DIV/0! | E15: =(E14-E8)/E8 -> #DIV/0! | F15: =(F14-F8)/F8 -> #DIV/0! | G15: =(G14-G8)/G8 -> #DIV/0! | H15: =(H14-H8)/H8 -> #DIV/0!
G16: Week Total | H16: =SUM(B14:H14) -> 0
A17: Breakfast | G17: % vPY | H17: =(H16-H9)/H9 -> #DIV/0!
A18: Greeter Total | C18: 337 | D18: 342 | E18: 328 | F18: 341 | G18: 283
A19: Non Meal Plan Meals
A20: Meal Plan Meals | C20: 0
A21: Total - Breakfast | B21: =SUM(B18:B20) -> 0 | C21: =SUM(C18:C20) -> 337 | D21: =SUM(D18:D20) -> 342 | E21: =SUM(E18:E20) -> 328 | F21: =SUM(F18:F20) -> 341 | G21: =SUM(G18:G20) -> 283 | H21: =SUM(H18:H20) -> 0
A22: % vPY Act | B22: =(B21-B5)/B5 -> #DIV/0! | C22: =(C21-C5)/C5 -> #DIV/0! | F22: =(F21-F5)/F5 -> #DIV/0! | G22: =(G21-G5)/G5 -> #DIV/0! | H22: =(H21-H5)/H5 -> #DIV/0!
A23: Lunch/Brunch | F23: Brunch/Lunch
A24: Greeter Total | C24: 660 | D24: 613 | E24: 616 | F24: 592 | G24: 479 | H24: 240
A25: Non Meal Plan Meals
A26: Meal Plan Meals
A27: Total - Lunch | B27: =SUM(B24:B26) -> 0 | C27: =C24+C25+C26 -> 660 | D27: =D24+D25+D26 -> 613 | E27: =E24+E25+E26 -> 616 | F27: =F24+F25+F26 -> 592 | G27: =G24+G25+G26 -> 479 | H27: =H24+H25+H26 -> 240
A28: % vPY Act | B28: =(B27-B6)/B6 -> #DIV/0! | C28: =(C27-C6)/C6 -> #DIV/0! | D28: =(D27-D6)/D6 -> #DIV/0! | E28: =(E27-E6)/E6 -> #DIV/0! | F28: =(F27-F6)/F6 -> #DIV/0! | G28: =(G27-G6)/G6 -> #DIV/0! | H28: =(H27-H6)/H6 -> #DIV/0!
A29: Dinner | F29: Dinner
A30: Greeter Total | C30: 652 | D30: 650 | E30: 560 | F30: 537 | G30: 173 | H30: 115
A31: Non Meal Plan Meals
A32: Meal Plan Meals
A33: Total - Dinner | B33: =SUM(B30:B32) -> 0 | C33: =SUM(C30:C32) -> 652 | D33: =SUM(D30:D32) -> 650 | E33: =SUM(E30:E32) -> 560 | F33: =SUM(F30:F32) -> 537 | G33: =SUM(G30:G32) -> 173 | H33: =SUM(H30:H32) -> 115
A34: % vPY Act | B34: =(B33-B7)/B7 -> #DIV/0! | C34: =(C33-C7)/C7 -> #DIV/0! | D34: =(D33-D7)/D7 -> #DIV/0! | E34: =(E33-E7)/E7 -> #DIV/0! | F34: =(F33-F7)/F7 -> #DIV/0! | G34: =(G33-G7)/G7 -> #DIV/0! | H34: =(H33-H7)/H7 -> #DIV/0!
A35: All Day | F35: Dinner
A36: Total - Day | B36: =B33+B27+B21 -> 0 | C36: =C33+C27+C21 -> 1649 | D36: =D33+D27+D21 -> 1605 | E36: =E33+E27+E21 -> 1504 | F36: =F33+F27+F21 -> 1470 | G36: =G33+G27+G21 -> 935 | H36: =H33+H27+H21 -> 355
A37: % vPY Act | B37: =(B36-B8)/B8 -> #DIV/0! | C37: =(C36-C8)/C8 -> #DIV/0! | D37: =(D36-D8)/D8 -> #DIV/0! | E37: =(E36-E8)/E8 -> #DIV/0! | F37: =(F36-F8)/F8 -> #DIV/0! | G37: =(G36-G8)/G8 -> #DIV/0! | H37: =(H36-H8)/H8 -> #DIV/0!
G38: Week Total | H38: =SUM(B36:H36) -> 7518
G39: % vPY Act | H39: =(H38-H9)/H9 -> #DIV/0!
G40: % vForecast | H40: =(H38-H16)/H16 -> #DIV/0!
...

Sheet Week 2
E1: Menu Cycle: | G1: Week:
B2: Sun | C2: Mon | D2: Tues | E2: Wed | F2: Thu | G2: Fri | H2: Sat
A3: Date | B3: ='OPENING WEEK 1'!H3+1 -> 45900 | C3: =B3+1 -> 45901 | D3: =C3+1 -> 45902 | E3: =D3+1 -> 45903 | F3: =E3+1 -> 45904 | G3: =F3+1 -> 45905 | H3: =G3+1 -> 45906
A4: Prior Year Actual - 2024
A5: Breakfast
A6: Lunch
A7: Dinner
A8: Total Day | B8: =B5+B6+B7 -> 0 | C8: =C5+C6+C7 -> 0 | D8: =D5+D6+D7 -> 0 | E8: =E5+E6+E7 -> 0 | F8: =F5+F6+F7 -> 0 | G8: =G5+G6+G7 -> 0 | H8: =H5+H6+H7 -> 0
G9: Week Total | H9: =SUM(B8:H8) -> 0
A10: Forecast - 2025 | G10: % Forecast Adj | H10: -0.08
A11: Breakfast | B11: =B5+(B5*H10) -> 0 | C11: =C5+(C5*H10) -> 0 | F11: =F5+(F5*H10) -> 0 | G11: =G5+(G5*H10) -> 0 | H11: =H5+(H5*H10) -> 0
A12: Lunch | B12: =B6+(B6*H10) -> 0 | C12: =C6+(C6*H10) -> 0 | D12: =D6+(D6*H10) -> 0 | E12: =E6+(E6*H10) -> 0 | F12: =F6+(F6*H10) -> 0 | G12: =G6+(G6*H10) -> 0 | H12: =H6+(H6*H10) -> 0
A13: Dinner | B13: =B7+(B7*H10) -> 0 | C13: =C7+(C7*H10) -> 0 | D13: =D7+(D7*H10) -> 0 | E13: =E7+(E7*H10) -> 0 | F13: =F7+(F7*H10) -> 0 | G13: =G7+(G7*H10) -> 0 | H13: =H7+(H7*H10) -> 0
A14: Total Day | B14: =B11+B12+B13 -> 0 | C14: =C11+C12+C13 -> 0 | D14: =D11+D12+D13 -> 0 | E14: =E11+E12+E13 -> 0 | F14: =F11+F12+F13 -> 0 | G14: =G11+G12+G13 -> 0 | H14: =H11+H12+H13 -> 0
A15: % vPY Act | B15: =(B14-B8)/B8 -> #DIV/0! | C15: =(C14-C8)/C8 -> #DIV/0! | D15: =(D14-D8)/D8 -> #DIV/0! | E15: =(E14-E8)/E8 -> #DIV/0! | F15: =(F14-F8)/F8 -> #DIV/0! | G15: =(G14-G8)/G8 -> #DIV/0! | H15: =(H14-H8)/H8 -> #DIV/0!
G16: Week Total | H16: =SUM(B14:H14) -> 0
A17: Breakfast | G17: % vPY | H17: =(H16-H9)/H9 -> #DIV/0!
A18: Greeter Total | D18: 325 | E18: 346 | F18: 264 | G18: 329
A19: ='OPENING WEEK 1'!A19 -> Non Meal Plan Meals
A20: ='OPENING WEEK 1'!A20 -> Meal Plan Meals
A21: Total - Breakfast | B21: =SUM(B18:B20) -> 0 | C21: =SUM(C18:C20) -> 0 | D21: =SUM(D18:D20) -> 325 | E21: =SUM(E18:E20) -> 346 | F21: =SUM(F18:F20) -> 264 | G21: =SUM(G18:G20) -> 329 | H21: =SUM(H18:H20) -> 0
A22: % vPY Act | B22: =(B21-B5)/B5 -> #DIV/0! | C22: =(C21-C5)/C5 -> #DIV/0! | F22: =(F21-F5)/F5 -> #DIV/0! | G22: =(G21-G5)/G5 -> #DIV/0! | H22: =(H21-H5)/H5 -> #DIV/0!
A23: Lunch/Brunch | F23: Brunch/Lunch
A24: Greeter Total | B24: 181 | C24: 260 | D24: 534 | E24: 574 | F24: 507 | G24: 500 | H24: 434
A25: ='OPENING WEEK 1'!A25 -> Non Meal Plan Meals
A26: ='OPENING WEEK 1'!A26 -> Meal Plan Meals
A27: ='OPENING WEEK 1'!A27 -> Total - Lunch | B27: =SUM(B24:B26) -> 181 | C27: =SUM(C24:C26) -> 260 | D27: =SUM(D24:D26) -> 534 | E27: =SUM(E24:E26) -> 574 | F27: =SUM(F24:F26) -> 507 | G27: =SUM(G24:G26) -> 500 | H27: =SUM(H24:H26) -> 434
A28: ='OPENING WEEK 1'!A28 -> % vPY Act | B28: =(B27-B6)/B6 -> #DIV/0! | C28: =(C27-C6)/C6 -> #DIV/0! | D28: =(D27-D6)/D6 -> #DIV/0! | E28: =(E27-E6)/E6 -> #DIV/0! | F28: =(F27-F6)/F6 -> #DIV/0! | G28: =(G27-G6)/G6 -> #DIV/0! | H28: =(H27-H6)/H6 -> #DIV/0!
A29: ='OPENING WEEK 1'!A29 -> Dinner | F29: Dinner
A30: ='OPENING WEEK 1'!A30 -> Greeter Total | B30: 167 | C30: 501 | D30: 596 | E30: 496 | F30: 600 | G30: 394 | H30: 237
A31: ='OPENING WEEK 1'!A31 -> Non Meal Plan Meals
A32: ='OPENING WEEK 1'!A32 -> Meal Plan Meals
A33: Total - Dinner | B33: =SUM(B30:B32) -> 167 | C33: =SUM(C30:C32) -> 501 | D33: =SUM(D30:D32) -> 596 | E33: =SUM(E30:E32) -> 496 | F33: =SUM(F30:F32) -> 600 | G33: =SUM(G30:G32) -> 394 | H33: =SUM(H30:H32) -> 237
A34: % vPY Act | B34: =(B33-B7)/B7 -> #DIV/0! | C34: =(C33-C7)/C7 -> #DIV/0! | D34: =(D33-D7)/D7 -> #DIV/0! | E34: =(E33-E7)/E7 -> #DIV/0! | F34: =(F33-F7)/F7 -> #DIV/0! | G34: =(G33-G7)/G7 -> #DIV/0! | H34: =(H33-H7)/H7 -> #DIV/0!
A35: All Day | F35: Dinner
A36: Total - Day | B36: =B33+B27+B21 -> 348 | C36: =C33+C27+C21 -> 761 | D36: =D33+D27+D21 -> 1455 | E36: =E33+E27+E21 -> 1416 | F36: =F33+F27+F21 -> 1371 | G36: =G33+G27+G21 -> 1223 | H36: =H33+H27+H21 -> 671
A37: % vPY Act | B37: =(B36-B8)/B8 -> #DIV/0! | C37: =(C36-C8)/C8 -> #DIV/0! | D37: =(D36-D8)/D8 -> #DIV/0! | E37: =(E36-E8)/E8 -> #DIV/0! | F37: =(F36-F8)/F8 -> #DIV/0! | G37: =(G36-G8)/G8 -> #DIV/0! | H37: =(H36-H8)/H8 -> #DIV/0!
G38: Week Total | H38: =SUM(B36:H36) -> 7245
G39: % vPY Act | H39: =(H38-H9)/H9 -> #DIV/0!
G40: % vForecast | H40: =(H38-H16)/H16 -> #DIV/0!
...

Sheet Week 3
E1: Menu Cycle: | G1: Week:
B2: Sun | C2: Mon | D2: Tues | E2: Wed | F2: Thu | G2: Fri | H2: Sat
A3: Date | B3: ='Week 2'!H3+1 -> 45907 | C3: =B3+1 -> 45908 | D3: =C3+1 -> 45909 | E3: =D3+1 -> 45910 | F3: =E3+1 -> 45911 | G3: =F3+1 -> 45912 | H3: =G3+1 -> 45913
A4: Prior Year Actual - 2024
A5: Breakfast | E5: 0
A6: Lunch | C6: 0 | D6: 0 | E6: 0
A7: Dinner | B7: 0 | C7: 0 | D7: 0 | E7: 0
A8: Total Day | B8: =B5+B6+B7 -> 0 | C8: =C5+C6+C7 -> 0 | D8: =D5+D6+D7 -> 0 | E8: =E5+E6+E7 -> 0 | F8: =F5+F6+F7 -> 0 | G8: =G5+G6+G7 -> 0 | H8: =H5+H6+H7 -> 0
G9: Week Total | H9: =SUM(B8:H8) -> 0
A10: Forecast - 2025 | G10: % Forecast Adj | H10: -0.08
A11: Breakfast | B11: =B5+(B5*H10) -> 0 | C11: =C5+(C5*H10) -> 0 | F11: =F5+(F5*H10) -> 0 | G11: =G5+(G5*H10) -> 0 | H11: =H5+(H5*H10) -> 0
A12: Lunch | B12: =B6+(B6*H10) -> 0 | C12: =C6+(C6*H10) -> 0 | D12: =D6+(D6*H10) -> 0 | E12: =E6+(E6*H10) -> 0 | F12: =F6+(F6*H10) -> 0 | G12: =G6+(G6*H10) -> 0 | H12: =H6+(H6*H10) -> 0
A13: Dinner | B13: =B7+(B7*H10) -> 0 | C13: =C7+(C7*H10) -> 0 | D13: =D7+(D7*H10) -> 0 | F13: =F7+(F7*H10) -> 0 | G13: =G7+(G7*H10) -> 0 | H13: =H7+(H7*H10) -> 0
A14: Total Day | B14: =SUM(B11:B13) -> 0 | C14: =SUM(C11:C13) -> 0 | D14: =SUM(D11:D13) -> 0 | E14: =SUM(E11:E13) -> 0 | F14: =SUM(F11:F13) -> 0 | G14: =SUM(G11:G13) -> 0 | H14: =SUM(H11:H13) -> 0
A15: % vPY Act | B15: =(B14-B8)/B8 -> #DIV/0! | C15: =(C14-C8)/C8 -> #DIV/0! | D15: =(D14-D8)/D8 -> #DIV/0! | E15: =(E14-E8)/E8 -> #DIV/0! | F15: =(F14-F8)/F8 -> #DIV/0! | G15: =(G14-G8)/G8 -> #DIV/0! | H15: =(H14-H8)/H8 -> #DIV/0!
G16: Week Total | H16: =SUM(B14:H14) -> 0
A17: Breakfast | G17: % vPY | H17: =(H16-H9)/H9 -> #DIV/0!
A18: Greeter Total | C18: 291 | D18: 310 | E18: 347 | F18: 275 | G18: 318
A19: Non Meal Plan Meals
A20: Meal Plan Meals
A21: Total - Breakfast | B21: =SUM(B18:B20) -> 0 | C21: =SUM(C18:C20) -> 291 | D21: =SUM(D18:D20) -> 310 | E21: =SUM(E18:E20) -> 347 | F21: =SUM(F18:F20) -> 275 | G21: =SUM(G18:G20) -> 318 | H21: =SUM(H18:H20) -> 0 | XFD21: =SUM(B21:XFC21) -> 1541
A22: % vPY Act | B22: =(B21-B5)/B5 -> #DIV/0! | C22: =(C21-C5)/C5 -> #DIV/0! | F22: =(F21-F5)/F5 -> #DIV/0! | G22: =(G21-G5)/G5 -> #DIV/0! | H22: =(H21-H5)/H5 -> #DIV/0!
A23: Lunch/Brunch | F23: Brunch/Lunch
A24: ='Week 2'!A24 -> Greeter Total | B24: 405 | C24: 599 | D24: 552 | E24: 607 | F24: 540 | G24: 578
A25: ='Week 2'!A25 -> Non Meal Plan Meals
A26: ='Week 2'!A26 -> Meal Plan Meals
A27: Total - Lunch | B27: =SUM(B24:B26) -> 405 | C27: =SUM(C24:C26) -> 599 | D27: =SUM(D24:D26) -> 552 | E27: =SUM(E24:E26) -> 607 | F27: =SUM(F24:F26) -> 540 | G27: =SUM(G24:G26) -> 578 | H27: =SUM(H24:H26) -> 0
A28: % vPY Act | B28: =(B27-B6)/B6 -> #DIV/0! | C28: =(C27-C6)/C6 -> #DIV/0! | D28: =(D27-D6)/D6 -> #DIV/0! | E28: =(E27-E6)/E6 -> #DIV/0! | F28: =(F27-F6)/F6 -> #DIV/0! | G28: =(G27-G6)/G6 -> #DIV/0! | H28: =(H27-H6)/H6 -> #DIV/0!
A29: Dinner | F29: Dinner
A30: Greeter Total | B30: 284 | C30: 594 | D30: 564 | E30: 628 | F30: 552 | G30: 378
A31: ='Week 2'!A31 -> Non Meal Plan Meals
A32: ='Week 2'!A32 -> Meal Plan Meals
A33: Total - Dinner | B33: =SUM(B30:B32) -> 284 | C33: =SUM(C30:C32) -> 594 | D33: =SUM(D30:D32) -> 564 | E33: =SUM(E30:E32) -> 628 | F33: =SUM(F30:F32) -> 552 | G33: =SUM(G30:G32) -> 378 | H33: =SUM(H30:H32) -> 0
A34: % vPY Act | B34: =(B33-B7)/B7 -> #DIV/0! | C34: =(C33-C7)/C7 -> #DIV/0! | D34: =(D33-D7)/D7 -> #DIV/0! | E34: =(E33-E7)/E7 -> #DIV/0! | F34: =(F33-F7)/F7 -> #DIV/0! | G34: =(G33-G7)/G7 -> #DIV/0! | H34: =(H33-H7)/H7 -> #DIV/0!
A35: All Day | F35: Dinner
A36: Total - Day | B36: =B33+B27+B21 -> 689 | C36: =C33+C27+C21 -> 1484 | D36: =D33+D27+D21 -> 1426 | E36: =E33+E27+E21 -> 1582 | F36: =F33+F27+F21 -> 1367 | G36: =G33+G27+G21 -> 1274 | H36: =H33+H27+H21 -> 0
A37: % vPY Act | B37: =(B36-B8)/B8 -> #DIV/0! | C37: =(C36-C8)/C8 -> #DIV/0! | D37: =(D36-D8)/D8 -> #DIV/0! | E37: =(E36-E8)/E8 -> #DIV/0! | F37: =(F36-F8)/F8 -> #DIV/0! | G37: =(G36-G8)/G8 -> #DIV/0! | H37: =(H36-H8)/H8 -> #DIV/0!
G38: Week Total | H38: =SUM(B36:H36) -> 7822
G39: % vPY Act | H39: =(H38-H9)/H9 -> #DIV/0!
G40: % vForecast | H40: =(H38-H16)/H16 -> #DIV/0!
...

Sheet Week 4
E1: Menu Cycle: | G1: Week:
B2: Sun | C2: Mon | D2: Tues | E2: Wed | F2: Thu | G2: Fri | H2: Sat
A3: Date | B3: ='Week 3'!H3+1 -> 45914 | C3: =B3+1 -> 45915 | D3: =C3+1 -> 45916 | E3: =D3+1 -> 45917 | F3: =E3+1 -> 45918 | G3: =F3+1 -> 45919 | H3: =G3+1 -> 45920
A4: Prior Year Actual - 2024
A5: Breakfast
A6: Lunch
A7: Dinner
A8: Total Day | B8: =B5+B6+B7 -> 0 | C8: =C5+C6+C7 -> 0 | D8: =D5+D6+D7 -> 0 | E8: =E5+E6+E7 -> 0 | F8: =F5+F6+F7 -> 0 | G8: =G5+G6+G7 -> 0 | H8: =H5+H6+H7 -> 0
G9: Week Total | H9: =SUM(B8:H8) -> 0
A10: Forecast - 2025 | G10: % Forecast Adj | H10: -0.08
A11: Breakfast | B11: =B5+(B5*H10) -> 0 | C11: =C5+(C5*H10) -> 0
A12: Lunch | B12: =B6+(B6*H10) -> 0 | C12: =C6+(C6*H10) -> 0 | D12: =D6+(D6*H10) -> 0 | E12: =E6+(E6*H10) -> 0
A13: Dinner | B13: =B7+(B7*H10) -> 0 | C13: =C7+(C7*H10) -> 0 | D13: =D7+(D7*H10) -> 0 | E13: =E7+(E7*H10) -> 0
A14: Total Day | B14: =SUM(B11:B13) -> 0 | C14: =SUM(C11:C13) -> 0 | D14: =SUM(D11:D13) -> 0 | E14: =SUM(E11:E13) -> 0 | F14: =SUM(F11:F13) -> 0 | G14: =SUM(G11:G13) -> 0 | H14: =SUM(H11:H13) -> 0
A15: % vPY Act | B15: =(B14-B8)/B8 -> #DIV/0! | C15: =(C14-C8)/C8 -> #DIV/0! | D15: =(D14-D8)/D8 -> #DIV/0! | E15: =(E14-E8)/E8 -> #DIV/0! | F15: =(F14-F8)/F8 -> #DIV/0! | G15: =(G14-G8)/G8 -> #DIV/0! | H15: =(H14-H8)/H8 -> #DIV/0!
G16: Week Total | H16: =SUM(B14:H14) -> 0
A17: Breakfast | G17: % vPY | H17: =(H16-H9)/H9 -> #DIV/0!
A18: ='Week 3'!A18 -> Greeter Total | C18: 289 | D18: 302 | E18: 348 | F18: 324
A19: ='Week 3'!A19 -> Non Meal Plan Meals
A20: ='Week 3'!A20 -> Meal Plan Meals
A21: Total - Breakfast | B21: =SUM(B18:B20) -> 0 | C21: =SUM(C18:C20) -> 289 | D21: =SUM(D18:D20) -> 302 | E21: =SUM(E18:E20) -> 348 | F21: =SUM(F18:F20) -> 324 | G21: =SUM(G18:G20) -> 0 | H21: =SUM(H18:H20) -> 0
A22: % vPY Act | B22: =(B21-B5)/B5 -> #DIV/0! | C22: =(C21-C5)/C5 -> #DIV/0! | F22: =(F21-F5)/F5 -> #DIV/0! | G22: =(G21-G5)/G5 -> #DIV/0! | H22: =(H21-H5)/H5 -> #DIV/0!
A23: Lunch/Brunch | F23: Brunch/Lunch
A24: =A18 -> Greeter Total | B24: 387 | C24: 553 | D24: 584 | E24: 554 | F24: 555
A25: =A19 -> Non Meal Plan Meals
A26: =A20 -> Meal Plan Meals
A27: Total - Lunch | B27: =SUM(B24:B26) -> 387 | C27: =SUM(C24:C26) -> 553 | D27: =SUM(D24:D26) -> 584 | E27: =SUM(E24:E26) -> 554 | F27: =SUM(F24:F26) -> 555 | G27: =SUM(G24:G26) -> 0 | H27: =SUM(H24:H26) -> 0
A28: % vPY Act | B28: =(B27-B6)/B6 -> #DIV/0! | C28: =(C27-C6)/C6 -> #DIV/0! | D28: =(D27-D6)/D6 -> #DIV/0! | E28: =(E27-E6)/E6 -> #DIV/0! | F28: =(F27-F6)/F6 -> #DIV/0! | G28: =(G27-G6)/G6 -> #DIV/0! | H28: =(H27-H6)/H6 -> #DIV/0!
A29: Dinner | F29: Dinner
A30: =A24 -> Greeter Total | B30: 280 | C30: 591 | D30: 667 | E30: 558 | F30: 584
A31: =A25 -> Non Meal Plan Meals
A32: =A26 -> Meal Plan Meals
A33: Total - Dinner | B33: =SUM(B30:B32) -> 280 | C33: =SUM(C30:C32) -> 591 | D33: =SUM(D30:D32) -> 667 | E33: =SUM(E30:E32) -> 558 | F33: =SUM(F30:F32) -> 584 | G33: =SUM(G30:G32) -> 0 | H33: =SUM(H30:H32) -> 0
A34: % vPY Act | B34: =(B33-B7)/B7 -> #DIV/0! | C34: =(C33-C7)/C7 -> #DIV/0! | D34: =(D33-D7)/D7 -> #DIV/0! | E34: =(E33-E7)/E7 -> #DIV/0! | F34: =(F33-F7)/F7 -> #DIV/0! | G34: =(G33-G7)/G7 -> #DIV/0! | H34: =(H33-H7)/H7 -> #DIV/0!
A35: All Day | F35: Dinner
A36: Total - Day | B36: =B33+B27+B21 -> 667 | C36: =C33+C27+C21 -> 1433 | D36: =D33+D27+D21 -> 1553 | E36: =E33+E27+E21 -> 1460 | F36: =F33+F27+F21 -> 1463 | G36: =G33+G27+G21 -> 0 | H36: =H33+H27+H21 -> 0
A37: % vPY Act | B37: =(B36-B8)/B8 -> #DIV/0! | C37: =(C36-C8)/C8 -> #DIV/0! | D37: =(D36-D8)/D8 -> #DIV/0! | E37: =(E36-E8)/E8 -> #DIV/0! | F37: =(F36-F8)/F8 -> #DIV/0! | G37: =(G36-G8)/G8 -> #DIV/0! | H37: =(H36-H8)/H8 -> #DIV/0!
G38: Week Total | H38: =SUM(B36:H36) -> 6576
G39: % vPY Act | H39: =(H38-H9)/H9 -> #DIV/0!
G40: % vForecast | H40: =(H38-H16)/H16 -> #DIV/0!
...

Sheet Week 5
E1: Menu Cycle: | G1: Week:
B2: Sun | C2: Mon | D2: Tues | E2: Wed | F2: Thu | G2: Fri | H2: Sat
A3: Date | B3: ='Week 4'!H3+1 -> 45921 | C3: =B3+1 -> 45922 | D3: =C3+1 -> 45923 | E3: =D3+1 -> 45924 | F3: =E3+1 -> 45925 | G3: =F3+1 -> 45926 | H3: =G3+1 -> 45927
A4: Prior Year Actual - 2024
A5: Breakfast
A6: Lunch
A7: Dinner
A8: Total Day | B8: =B5+B6+B7 -> 0 | C8: =C5+C6+C7 -> 0 | D8: =D5+D6+D7 -> 0 | E8: =E5+E6+E7 -> 0 | F8: =F5+F6+F7 -> 0 | G8: =G5+G6+G7 -> 0 | H8: =H5+H6+H7 -> 0
G9: Week Total | H9: =SUM(B8:H8) -> 0
A10: Forecast - 2025 | G10: % Forecast Adj | H10: -0.08
A11: Breakfast
A12: Lunch
A13: Dinner
A14: Total Day | B14: =B11+B12+B13 -> 0 | C14: =C11+C12+C13 -> 0 | D14: =D11+D12+D13 -> 0 | E14: =E11+E12+E13 -> 0 | F14: =F11+F12+F13 -> 0 | G14: =G11+G12+G13 -> 0 | H14: =H11+H12+H13 -> 0
A15: % vPY Act | B15: =(B14-B8)/B8 -> #DIV/0! | C15: =(C14-C8)/C8 -> #DIV/0! | D15: =(D14-D8)/D8 -> #DIV/0! | E15: =(E14-E8)/E8 -> #DIV/0! | F15: =(F14-F8)/F8 -> #DIV/0! | G15: =(G14-G8)/G8 -> #DIV/0! | H15: =(H14-H8)/H8 -> #DIV/0!
G16: Week Total | H16: =SUM(B14:H14) -> 0
A17: Breakfast | G17: % vPY | H17: =(H16-H9)/H9 -> #DIV/0!
A18: ='Week 4'!A18 -> Greeter Total | D18: 307 | E18: 303 | F18: 257 | G18: 280
A19: ='Week 4'!A19 -> Non Meal Plan Meals
A20: Meal numbers
A21: Total - Breakfast | B21: =SUM(B18:B20) -> 0 | C21: =SUM(C18:C20) -> 0 | D21: =SUM(D18:D20) -> 307 | E21: =SUM(E18:E20) -> 303 | F21: =SUM(F18:F20) -> 257 | G21: =SUM(G18:G20) -> 280 | H21: =SUM(H18:H20) -> 0
A22: % vPY Act | B22: =(B21-B5)/B5 -> #DIV/0! | C22: =(C21-C5)/C5 -> #DIV/0! | F22: =(F21-F5)/F5 -> #DIV/0! | G22: =(G21-G5)/G5 -> #DIV/0! | H22: =(H21-H5)/H5 -> #DIV/0!
A23: Lunch/Brunch | F23: Brunch/Lunch
A24: =A18 -> Greeter Total | D24: 589 | E24: 553 | F24: 540 | G24: 579 | H24: 380
A25: =A19 -> Non Meal Plan Meals
A26: =A20 -> Meal numbers
A27: Total - Lunch | B27: =SUM(B24:B26) -> 0 | C27: =SUM(C24:C26) -> 0 | D27: =SUM(D24:D26) -> 589 | E27: =SUM(E24:E26) -> 553 | F27: =SUM(F24:F26) -> 540 | G27: =SUM(G24:G26) -> 579 | H27: =SUM(H24:H26) -> 380
A28: % vPY Act | B28: =(B27-B6)/B6 -> #DIV/0! | C28: =(C27-C6)/C6 -> #DIV/0! | D28: =(D27-D6)/D6 -> #DIV/0! | E28: =(E27-E6)/E6 -> #DIV/0! | F28: =(F27-F6)/F6 -> #DIV/0! | G28: =(G27-G6)/G6 -> #DIV/0! | H28: =(H27-H6)/H6 -> #DIV/0!
A29: Dinner | F29: Dinner
A30: =A24 -> Greeter Total | D30: 551 | E30: 562 | F30: 519 | G30: 292 | H30: 179
A31: =A25 -> Non Meal Plan Meals
A32: =A26 -> Meal numbers
A33: Total - Dinner | B33: =SUM(B30:B32) -> 0 | C33: =SUM(C30:C32) -> 0 | D33: =SUM(D30:D32) -> 551 | E33: =SUM(E30:E32) -> 562 | F33: =SUM(F30:F32) -> 519 | G33: =SUM(G30:G32) -> 292 | H33: =SUM(H30:H32) -> 179
A34: % vPY Act | B34: =(B33-B7)/B7 -> #DIV/0! | C34: =(C33-C7)/C7 -> #DIV/0! | D34: =(D33-D7)/D7 -> #DIV/0! | E34: =(E33-E7)/E7 -> #DIV/0! | F34: =(F33-F7)/F7 -> #DIV/0! | G34: =(G33-G7)/G7 -> #DIV/0! | H34: =(H33-H7)/H7 -> #DIV/0!
A35: All Day | F35: Dinner
A36: Total - Day | B36: =B33+B27+B21 -> 0 | C36: =C33+C27+C21 -> 0 | D36: =D33+D27+D21 -> 1447 | E36: =E33+E27+E21 -> 1418 | F36: =F33+F27+F21 -> 1316 | G36: =G33+G27+G21 -> 1151 | H36: =H33+H27+H21 -> 559
A37: % vPY Act | B37: =(B36-B8)/B8 -> #DIV/0! | C37: =(C36-C8)/C8 -> #DIV/0! | D37: =(D36-D8)/D8 -> #DIV/0! | E37: =(E36-E8)/E8 -> #DIV/0! | F37: =(F36-F8)/F8 -> #DIV/0! | G37: =(G36-G8)/G8 -> #DIV/0! | H37: =(H36-H8)/H8 -> #DIV/0!
G38: Week Total | H38: =SUM(B36:H36) -> 5891
G39: % vPY Act | H39: =(H38-H9)/H9 -> #DIV/0!
G40: % vForecast | H40: =(H38-H16)/H16 -> #DIV/0!
...

Sheet Average w3-5
E1: Menu Cycle: | G1: Week:
B2: Fri | C2: Sat | D2: Sun | E2: Mon | F2: Tue | G2: Wed | H2: Thu
A3: Date
A4: Prior Year Actual-2024
A5: Breakfast | B5: =('Week 5'!B5+'Week 4'!B5+'Week 3'!B5)/3 -> 0 | C5: =('Week 5'!C5+'Week 4'!C5+'Week 3'!C5)/3 -> 0 | D5: =('Week 5'!D5+'Week 4'!D5+'Week 3'!D5)/3 -> 0 | E5: =('Week 5'!E5+'Week 4'!E5+'Week 3'!E5)/3 -> 0 | F5: =('Week 5'!F5+'Week 4'!F5+'Week 3'!F5)/3 -> 0 | G5: =('Week 5'!G5+'Week 4'!G5+'Week 3'!G5)/3 -> 0 | H5: =('Week 5'!H5+'Week 4'!H5+'Week 3'!H5)/3 -> 0
A6: Lunch | B6: =('Week 5'!B6+'Week 4'!B6+'Week 3'!B6)/3 -> 0 | C6: =('Week 5'!C6+'Week 4'!C6+'Week 3'!C6)/3 -> 0 | D6: =('Week 5'!D6+'Week 4'!D6+'Week 3'!D6)/3 -> 0 | E6: =('Week 5'!E6+'Week 4'!E6+'Week 3'!E6)/3 -> 0 | F6: =('Week 5'!F6+'Week 4'!F6+'Week 3'!F6)/3 -> 0 | G6: =('Week 5'!G6+'Week 4'!G6+'Week 3'!G6)/3 -> 0 | H6: =('Week 5'!H6+'Week 4'!H6+'Week 3'!H6)/3 -> 0
A7: Dinner | B7: =('Week 5'!B7+'Week 4'!B7+'Week 3'!B7)/3 -> 0 | C7: =('Week 5'!C7+'Week 4'!C7+'Week 3'!C7)/3 -> 0 | D7: =('Week 5'!D7+'Week 4'!D7+'Week 3'!D7)/3 -> 0 | E7: =('Week 5'!E7+'Week 4'!E7+'Week 3'!E7)/3 -> 0 | F7: =('Week 5'!F7+'Week 4'!F7+'Week 3'!F7)/3 -> 0 | G7: =('Week 5'!G7+'Week 4'!G7+'Week 3'!G7)/3 -> 0 | H7: =('Week 5'!H7+'Week 4'!H7+'Week 3'!H7)/3 -> 0
A8: Total Day | B8: =B5+B6+B7 -> 0 | C8: =C5+C6+C7 -> 0 | D8: =D5+D6+D7 -> 0 | E8: =E5+E6+E7 -> 0 | F8: =F5+F6+F7 -> 0 | G8: =G5+G6+G7 -> 0 | H8: =H5+H6+H7 -> 0
G9: Week Total | H9: =SUM(B8:H8) -> 0
A10: Forecast-2025 | G10: % Forecast Adj | H10: 0
A11: Breakfast | B11: =('Week 5'!B11+'Week 4'!B11+'Week 3'!B11)/3 -> 0 | C11: =('Week 5'!C11+'Week 4'!C11+'Week 3'!C11)/3 -> 0 | D11: =('Week 5'!D11+'Week 4'!D11+'Week 3'!D11)/3 -> 0 | E11: =('Week 5'!E11+'Week 4'!E11+'Week 3'!E11)/3 -> 0 | F11: =('Week 5'!F11+'Week 4'!F11+'Week 3'!F11)/3 -> 0 | G11: =('Week 5'!G11+'Week 4'!G11+'Week 3'!G11)/3 -> 0 | H11: =('Week 5'!H11+'Week 4'!H11+'Week 3'!H11)/3 -> 0
A12: Lunch | B12: =('Week 5'!B12+'Week 4'!B12+'Week 3'!B12)/3 -> 0 | C12: =('Week 5'!C12+'Week 4'!C12+'Week 3'!C12)/3 -> 0 | D12: =('Week 5'!D12+'Week 4'!D12+'Week 3'!D12)/3 -> 0 | E12: =('Week 5'!E12+'Week 4'!E12+'Week 3'!E12)/3 -> 0 | F12: =('Week 5'!F12+'Week 4'!F12+'Week 3'!F12)/3 -> 0 | G12: =('Week 5'!G12+'Week 4'!G12+'Week 3'!G12)/3 -> 0 | H12: =('Week 5'!H12+'Week 4'!H12+'Week 3'!H12)/3 -> 0
A13: Dinner | B13: =('Week 5'!B13+'Week 4'!B13+'Week 3'!B13)/3 -> 0 | C13: =('Week 5'!C13+'Week 4'!C13+'Week 3'!C13)/3 -> 0 | D13: =('Week 5'!D13+'Week 4'!D13+'Week 3'!D13)/3 -> 0 | E13: =('Week 5'!E13+'Week 4'!E13+'Week 3'!E13)/3 -> 0 | F13: =('Week 5'!F13+'Week 4'!F13+'Week 3'!F13)/3 -> 0 | G13: =('Week 5'!G13+'Week 4'!G13+'Week 3'!G13)/3 -> 0 | H13: =('Week 5'!H13+'Week 4'!H13+'Week 3'!H13)/3 -> 0
A14: Total Day | B14: =B11+B12+B13 -> 0 | C14: =C11+C12+C13 -> 0 | D14: =D11+D12+D13 -> 0 | E14: =E11+E12+E13 -> 0 | F14: =F11+F12+F13 -> 0 | G14: =G11+G12+G13 -> 0 | H14: =H11+H12+H13 -> 0
A15: % vPY Act | B15: =(B14-B8)/B8 -> #DIV/0! | C15: =(C14-C8)/C8 -> #DIV/0! | D15: =(D14-D8)/D8 -> #DIV/0! | E15: =(E14-E8)/E8 -> #DIV/0! | F15: =(F14-F8)/F8 -> #DIV/0! | G15: =(G14-G8)/G8 -> #DIV/0! | H15: =(H14-H8)/H8 -> #DIV/0!
G16: Week Total | H16: =SUM(B14:H14) -> 0
A17: Breakfast | G17: % vPY | H17: =(H16-H9)/H9 -> #DIV/0!
A18: ='Week 5'!A30 -> Greeter Total
A19: ='Week 5'!A31 -> Non Meal Plan Meals
A20: ='Week 5'!A32 -> Meal numbers
A21: Total - Breakfast | B21: =('Week 5'!B21+'Week 4'!B21+'Week 3'!B21)/3 -> 0 | C21: =('Week 5'!C21+'Week 4'!C21+'Week 3'!C21)/3 -> 193.33333 | D21: =('Week 5'!D21+'Week 4'!D21+'Week 3'!D21)/3 -> 306.33333 | E21: =('Week 5'!E21+'Week 4'!E21+'Week 3'!E21)/3 -> 332.66667 | F21: =('Week 5'!F21+'Week 4'!F21+'Week 3'!F21)/3 -> 285.33333 | G21: =('Week 5'!G21+'Week 4'!G21+'Week 3'!G21)/3 -> 199.33333 | H21: =('Week 5'!H21+'Week 4'!H21+'Week 3'!H21)/3 -> 0
A22: % vPY Act | B22: =(B21-B5)/B5 -> #DIV/0! | C22: =(C21-C5)/C5 -> #DIV/0! | F22: =(F21-F5)/F5 -> #DIV/0! | G22: =(G21-G5)/G5 -> #DIV/0! | H22: =(H21-H5)/H5 -> #DIV/0!
A23: Lunch/Brunch | F23: Brunch/Lunch
A24: =A18 -> Greeter Total
A25: =A19 -> Non Meal Plan Meals
A26: =A20 -> Meal numbers
A27: Total - Lunch | B27: =('Week 5'!B27+'Week 4'!B27+'Week 3'!B27)/3 -> 264 | C27: =('Week 5'!C27+'Week 4'!C27+'Week 3'!C27)/3 -> 384 | D27: =('Week 5'!D27+'Week 4'!D27+'Week 3'!D27)/3 -> 575 | E27: =('Week 5'!E27+'Week 4'!E27+'Week 3'!E27)/3 -> 571.33333 | F27: =('Week 5'!F27+'Week 4'!F27+'Week 3'!F27)/3 -> 545 | G27: =('Week 5'!G27+'Week 4'!G27+'Week 3'!G27)/3 -> 385.66667 | H27: =('Week 5'!H27+'Week 4'!H27+'Week 3'!H27)/3 -> 126.66667
A28: % vPY Act | B28: =(B27-B6)/B6 -> #DIV/0! | C28: =(C27-C6)/C6 -> #DIV/0! | D28: =(D27-D6)/D6 -> #DIV/0! | E28: =(E27-E6)/E6 -> #DIV/0! | F28: =(F27-F6)/F6 -> #DIV/0! | G28: =(G27-G6)/G6 -> #DIV/0! | H28: =(H27-H6)/H6 -> #DIV/0!
A29: Dinner | F29: Dinner
A30: =A24 -> Greeter Total
A31: =A25 -> Non Meal Plan Meals
A32: =A26 -> Meal numbers
A33: Total - Dinner | B33: =('Week 5'!B33+'Week 4'!B33+'Week 3'!B33)/3 -> 188 | C33: =('Week 5'!C33+'Week 4'!C33+'Week 3'!C33)/3 -> 395 | D33: =('Week 5'!D33+'Week 4'!D33+'Week 3'!D33)/3 -> 594 | E33: =('Week 5'!E33+'Week 4'!E33+'Week 3'!E33)/3 -> 582.66667 | F33: =('Week 5'!F33+'Week 4'!F33+'Week 3'!F33)/3 -> 551.66667 | G33: =('Week 5'!G33+'Week 4'!G33+'Week 3'!G33)/3 -> 223.33333 | H33: =('Week 5'!H33+'Week 4'!H33+'Week 3'!H33)/3 -> 59.666667
A34: % vPY Act | B34: =(B33-B7)/B7 -> #DIV/0! | C34: =(C33-C7)/C7 -> #DIV/0! | D34: =(D33-D7)/D7 -> #DIV/0! | E34: =(E33-E7)/E7 -> #DIV/0! | F34: =(F33-F7)/F7 -> #DIV/0! | G34: =(G33-G7)/G7 -> #DIV/0! | H34: =(H33-H7)/H7 -> #DIV/0!
A35: All Day | F35: Dinner
A36: Total - Day | B36: =('Week 5'!B36+'Week 4'!B36+'Week 3'!B36)/3 -> 452 | C36: =('Week 5'!C36+'Week 4'!C36+'Week 3'!C36)/3 -> 972.33333 | D36: =('Week 5'!D36+'Week 4'!D36+'Week 3'!D36)/3 -> 1475.3333 | E36: =('Week 5'!E36+'Week 4'!E36+'Week 3'!E36)/3 -> 1486.6667 | F36: =('Week 5'!F36+'Week 4'!F36+'Week 3'!F36)/3 -> 1382 | G36: =('Week 5'!G36+'Week 4'!G36+'Week 3'!G36)/3 -> 808.33333 | H36: =('Week 5'!H36+'Week 4'!H36+'Week 3'!H36)/3 -> 186.33333
A37: % vPY Act | B37: =(B36-B8)/B8 -> #DIV/0! | C37: =(C36-C8)/C8 -> #DIV/0! | D37: =(D36-D8)/D8 -> #DIV/0! | E37: =(E36-E8)/E8 -> #DIV/0! | F37: =(F36-F8)/F8 -> #DIV/0! | G37: =(G36-G8)/G8 -> #DIV/0! | H37: =(H36-H8)/H8 -> #DIV/0!
G38: Week Total | H38: =SUM(B36:H36) -> 6763
G39: % vPY Act | H39: =(H38-H9)/H9 -> #DIV/0!
G40: % vForecast | H40: =(H38-H16)/H16 -> #DIV/0!
...

Sheet Week 6
E1: Menu Cycle: | G1: Week:
B2: Sun | C2: Mon | D2: Tues | E2: Wed | F2: Thu | G2: Fri | H2: Sat
A3: Date | B3: ='Week 5'!H3+1 -> 45928 | C3: =B3+1 -> 45929 | D3: =C3+1 -> 45930 | E3: =D3+1 -> 45931 | F3: =E3+1 -> 45932 | G3: =F3+1 -> 45933 | H3: =G3+1 -> 45934
A4: Prior Year Actual - 2024
A5: Breakfast
A6: Lunch
A7: Dinner
A8: Total Day | B8: =B5+B6+B7 -> 0 | C8: =C5+C6+C7 -> 0 | D8: =D5+D6+D7 -> 0 | E8: =E5+E6+E7 -> 0
G9: Week Total | H9: =SUM(B8:H8) -> 0
A10: Forecast -2025 | G10: % Forecast Adj | H10: -0.08
A11: Breakfast
A12: Lunch
A13: Dinner
A14: Total Day | B14: =SUM(B11:B13) -> 0 | C14: =SUM(C11:C13) -> 0 | D14: =SUM(D11:D13) -> 0 | E14: =SUM(E11:E13) -> 0 | F14: =SUM(F11:F13) -> 0 | G14: =SUM(G11:G13) -> 0 | H14: =SUM(H11:H13) -> 0
A15: % vPY Act | B15: =(B14-B8)/B8 -> #DIV/0! | C15: =(C14-C8)/C8 -> #DIV/0! | D15: =(D14-D8)/D8 -> #DIV/0! | E15: =(E14-E8)/E8 -> #DIV/0! | F15: =(F14-F8)/F8 -> #DIV/0! | G15: =(G14-G8)/G8 -> #DIV/0! | H15: =(H14-H8)/H8 -> #DIV/0!
G16: Week Total | H16: =SUM(B14:H14) -> 0
A17: Breakfast | G17: % vPY | H17: =(H16-H9)/H9 -> #DIV/0!
A18: Greeter Total | C18: 262
A19: ='Average w3-5'!A31 -> Non Meal Plan Meals
A20: ='Average w3-5'!A32 -> Meal numbers
A21: Total - Breakfast | B21: =SUM(B18:B20) -> 0 | C21: =SUM(C18:C20) -> 262 | F21: =SUM(F18:F20) -> 0 | G21: =SUM(G18:G20) -> 0 | H21: =SUM(H18:H20) -> 0
A22: % vPY Act | B22: =(B21-B5)/B5 -> #DIV/0! | C22: =(C21-C5)/C5 -> #DIV/0! | F22: =(F21-F5)/F5 -> #DIV/0! | G22: =(G21-G5)/G5 -> #DIV/0! | H22: =(H21-H5)/H5 -> #DIV/0!
A23: Lunch/Brunch | F23: Brunch/Lunch
A24: Greeter Total | B24: 313 | C24: 658
A25: =A19 -> Non Meal Plan Meals
A26: =A20 -> Meal numbers
A27: Total - Lunch | B27: =SUM(B24:B26) -> 313 | C27: =SUM(C24:C26) -> 658 | D27: =SUM(D24:D26) -> 0 | E27: =SUM(E24:E26) -> 0 | F27: =SUM(F24:F26) -> 0 | G27: =SUM(G24:G26) -> 0 | H27: =SUM(H24:H26) -> 0
A28: % vPY Act | B28: =(B27-B6)/B6 -> #DIV/0! | C28: =(C27-C6)/C6 -> #DIV/0! | D28: =(D27-D6)/D6 -> #DIV/0! | E28: =(E27-E6)/E6 -> #DIV/0! | F28: =(F27-F6)/F6 -> #DIV/0! | G28: =(G27-G6)/G6 -> #DIV/0! | H28: =(H27-H6)/H6 -> #DIV/0!
A29: Dinner | F29: Dinner
A30: Greeter Total | B30: 283 | C30: 627
A31: =A25 -> Non Meal Plan Meals
A32: =A26 -> Meal numbers
A33: Total - Dinner | B33: =B30+B31+B32 -> 283 | C33: =C30+C31+C32 -> 627 | D33: =D30+D31+D32 -> 0 | E33: =E30+E31+E32 -> 0 | F33: =SUM(F30:F32) -> 0 | G33: =SUM(G30:G32) -> 0 | H33: =SUM(H30:H32) -> 0
A34: % vPY Act | B34: =(B33-B7)/B7 -> #DIV/0! | C34: =(C33-C7)/C7 -> #DIV/0! | D34: =(D33-D7)/D7 -> #DIV/0! | E34: =(E33-E7)/E7 -> #DIV/0! | F34: =(F33-F7)/F7 -> #DIV/0! | G34: =(G33-G7)/G7 -> #DIV/0! | H34: =(H33-H7)/H7 -> #DIV/0!
A35: All Day | F35: Dinner
A36: Total - Day | B36: =B33+B27+B21 -> 596 | C36: =C33+C27+C21 -> 1547 | D36: =D33+D27+D21 -> 0 | E36: =E33+E27+E21 -> 0 | F36: =F33+F27+F21 -> 0 | G36: =G33+G27+G21 -> 0 | H36: =H33+H27+H21 -> 0
A37: % vPY Act | B37: =(B36-B8)/B8 -> #DIV/0! | C37: =(C36-C8)/C8 -> #DIV/0! | D37: =(D36-D8)/D8 -> #DIV/0! | E37: =(E36-E8)/E8 -> #DIV/0! | F37: =(F36-F8)/F8 -> #DIV/0! | G37: =(G36-G8)/G8 -> #DIV/0! | H37: =(H36-H8)/H8 -> #DIV/0!
G38: Week Total | H38: =SUM(B36:H36) -> 2143
G39: % vPY Act | H39: =(H38-H9)/H9 -> #DIV/0!
G40: % vForecast | H40: =(H38-H16)/H16 -> #DIV/0!
...

Sheet Week 7
E1: Menu Cycle: | G1: Week:
B2: Fri | C2: Sat | D2: Sun | E2: Mon | F2: Tue | G2: Wed | H2: Thu
A3: Date | B3: ='Week 6'!H3+1 -> 45935 | C3: =B3+1 -> 45936 | D3: =C3+1 -> 45937 | E3: =D3+1 -> 45938 | F3: =E3+1 -> 45939 | G3: =F3+1 -> 45940 | H3: =G3+1 -> 45941
A4: Prior Year Actual - 2024
A5: Breakfast
A6: Lunch
A7: Dinner
A8: Total Day | B8: =B5+B6+B7 -> 0 | C8: =C5+C6+C7 -> 0 | D8: =D5+D6+D7 -> 0 | E8: =E5+E6+E7 -> 0 | F8: =F5+F6+F7 -> 0 | G8: =G5+G6+G7 -> 0 | H8: =H5+H6+H7 -> 0
G9: Week Total | H9: =SUM(B8:H8) -> 0
A10: Forecast - 2025 | G10: % Forecast Adj | H10: -0.08
A11: Breakfast
A12: Lunch
A13: Dinner
A14: Total Day | B14: =SUM(B11:B13) -> 0 | C14: =SUM(C11:C13) -> 0 | D14: =SUM(D11:D13) -> 0 | E14: =SUM(E11:E13) -> 0 | F14: =SUM(F11:F13) -> 0 | G14: =SUM(G11:G13) -> 0 | H14: =SUM(H11:H13) -> 0
A15: % vPY Act | B15: =(B14-B8)/B8 -> #DIV/0! | C15: =(C14-C8)/C8 -> #DIV/0! | D15: =(D14-D8)/D8 -> #DIV/0! | E15: =(E14-E8)/E8 -> #DIV/0! | F15: =(F14-F8)/F8 -> #DIV/0! | G15: =(G14-G8)/G8 -> #DIV/0! | H15: =(H14-H8)/H8 -> #DIV/0!
G16: Week Total | H16: =SUM(B14:H14) -> 0
A17: Breakfast | G17: % vPY | H17: =(H16-H9)/H9 -> #DIV/0!
A18: Greeter Total
A19: ='Week 6'!A25 -> Non Meal Plan Meals
A20: ='Week 6'!A26 -> Meal numbers
A21: Total - Breakfast | B21: =SUM(B18:B20) -> 0 | C21: =SUM(C18:C20) -> 0 | D21: =SUM(D18:D20) -> 0 | E21: =SUM(E18:E20) -> 0 | F21: =SUM(F18:F20) -> 0 | G21: =SUM(G18:G20) -> 0 | H21: =SUM(H18:H20) -> 0
A22: % vPY Act | B22: =(B21-B5)/B5 -> #DIV/0! | C22: =(C21-C5)/C5 -> #DIV/0! | F22: =(F21-F5)/F5 -> #DIV/0! | G22: =(G21-G5)/G5 -> #DIV/0! | H22: =(H21-H5)/H5 -> #DIV/0!
A23: Lunch/Brunch | F23: Brunch/Lunch
A24: Greeter Total
A25: ='Week 6'!A31 -> Non Meal Plan Meals
A26: ='Week 6'!A32 -> Meal numbers
A27: Isolation meals
A28: Total - Lunch | B28: =SUM(B24:B27) -> 0 | C28: =SUM(C24:C27) -> 0 | D28: =SUM(D24:D27) -> 0 | E28: =SUM(E24:E27) -> 0 | F28: =SUM(F24:F27) -> 0 | G28: =SUM(G24:G27) -> 0 | H28: =SUM(H24:H27) -> 0
A29: % vPY Act | B29: =(B28-B6)/B6 -> #DIV/0! | C29: =(C28-C6)/C6 -> #DIV/0! | D29: =(D28-D6)/D6 -> #DIV/0! | E29: =(E28-E6)/E6 -> #DIV/0! | F29: =(F28-F6)/F6 -> #DIV/0! | G29: =(G28-G6)/G6 -> #DIV/0! | H29: =(H28-H6)/H6 -> #DIV/0!
A30: Dinner | F30: Dinner
A31: Greeter Total
A32: =A25 -> Non Meal Plan Meals
A33: =A26 -> Meal numbers
A34: Total - Dinner | B34: =SUM(B31:B33) -> 0 | C34: =SUM(C31:C33) -> 0 | D34: =SUM(D31:D33) -> 0 | E34: =SUM(E31:E33) -> 0 | F34: =SUM(F31:F33) -> 0 | G34: =SUM(G31:G33) -> 0 | H34: =SUM(H31:H33) -> 0
A35: % vPY Act | B35: =(B34-B7)/B7 -> #DIV/0! | C35: =(C34-C7)/C7 -> #DIV/0! | D35: =(D34-D7)/D7 -> #DIV/0! | E35: =(E34-E7)/E7 -> #DIV/0! | F35: =(F34-F7)/F7 -> #DIV/0! | G35: =(G34-G7)/G7 -> #DIV/0! | H35: =(H34-H7)/H7 -> #DIV/0!
A36: All Day | F36: Dinner
A37: Total - Day | B37: =B34+B28+B21 -> 0 | C37: =C34+C28+C21 -> 0 | D37: =D34+D28+D21 -> 0 | E37: =E34+E28+E21 -> 0 | F37: =F34+F28+F21 -> 0 | G37: =G34+G28+G21 -> 0 | H37: =H34+H28+H21 -> 0
A38: % vPY Act | B38: =(B37-B8)/B8 -> #DIV/0! | C38: =(C37-C8)/C8 -> #DIV/0! | D38: =(D37-D8)/D8 -> #DIV/0! | E38: =(E37-E8)/E8 -> #DIV/0! | F38: =(F37-F8)/F8 -> #DIV/0! | G38: =(G37-G8)/G8 -> #DIV/0! | H38: =(H37-H8)/H8 -> #DIV/0!
G39: Week Total | H39: =SUM(B37:H37) -> 0
G40: % vPY Act | H40: =(H39-H9)/H9 -> #DIV/0!
...

Sheet Week 8
E1: Menu Cycle: | G1: Week:
B2: Fri | C2: Sat | D2: Sun | E2: Mon | F2: Tue | G2: Wed | H2: Thu
A3: Date | B3: ='Week 7'!H3+1 -> 45942 | C3: =B3+1 -> 45943 | D3: =C3+1 -> 45944 | E3: =D3+1 -> 45945 | F3: =E3+1 -> 45946 | G3: =F3+1 -> 45947 | H3: =G3+1 -> 45948
A4: Prior Year Actual-2024
A5: Breakfast
A6: Lunch
A7: Dinner
A8: Total Day | B8: =B5+B6+B7 -> 0 | C8: =C5+C6+C7 -> 0 | D8: =D5+D6+D7 -> 0 | E8: =E5+E6+E7 -> 0 | F8: =F5+F6+F7 -> 0 | G8: =G5+G6+G7 -> 0 | H8: =H5+H6+H7 -> 0
G9: Week Total | H9: =SUM(B8:H8) -> 0
A10: Forecast - 2025 | G10: % Forecast Adj | H10: -0.08
A11: Breakfast
A12: Lunch
A13: Dinner
A14: Total Day | B14: =SUM(B11:B13) -> 0 | C14: =SUM(C11:C13) -> 0 | D14: =SUM(D11:D13) -> 0 | E14: =SUM(E11:E13) -> 0 | F14: =SUM(F11:F13) -> 0 | G14: =SUM(G11:G13) -> 0 | H14: =SUM(H11:H13) -> 0
A15: % vPY Act | B15: =(B14-B8)/B8 -> #DIV/0! | C15: =(C14-C8)/C8 -> #DIV/0! | D15: =(D14-D8)/D8 -> #DIV/0! | E15: =(E14-E8)/E8 -> #DIV/0! | F15: =(F14-F8)/F8 -> #DIV/0! | G15: =(G14-G8)/G8 -> #DIV/0! | H15: =(H14-H8)/H8 -> #DIV/0!
G16: Week Total | H16: =SUM(B14:H14) -> 0
A17: Breakfast | G17: % vPY | H17: =(H16-H9)/H9 -> #DIV/0!
A18: Greeter Total
A19: ='Week 7'!A32 -> Non Meal Plan Meals
A20: ='Week 7'!A33 -> Meal numbers
A21: Total - Breakfast | B21: =SUM(B18:B20) -> 0 | C21: =SUM(C18:C20) -> 0 | D21: =SUM(D18:D20) -> 0 | E21: =SUM(E18:E20) -> 0 | F21: =SUM(F18:F20) -> 0 | G21: =SUM(G18:G20) -> 0 | H21: =SUM(H18:H20) -> 0
A22: % vPY Act | B22: =(B21-B5)/B5 -> #DIV/0! | C22: =(C21-C5)/C5 -> #DIV/0! | F22: =(F21-F5)/F5 -> #DIV/0! | G22: =(G21-G5)/G5 -> #DIV/0! | H22: =(H21-H5)/H5 -> #DIV/0!
A23: Lunch/Brunch | F23: Brunch/Lunch
A24: Greeter Total
A25: =A19 -> Non Meal Plan Meals
A26: =A20 -> Meal numbers
A27: Total - Lunch | B27: =SUM(B24:B26) -> 0 | C27: =SUM(C24:C26) -> 0 | D27: =SUM(D24:D26) -> 0 | E27: =SUM(E24:E26) -> 0 | F27: =SUM(F24:F26) -> 0 | G27: =SUM(G24:G26) -> 0 | H27: =SUM(H24:H26) -> 0
A28: % vPY Act | B28: =(B27-B6)/B6 -> #DIV/0! | C28: =(C27-C6)/C6 -> #DIV/0! | D28: =(D27-D6)/D6 -> #DIV/0! | E28: =(E27-E6)/E6 -> #DIV/0! | F28: =(F27-F6)/F6 -> #DIV/0! | G28: =(G27-G6)/G6 -> #DIV/0! | H28: =(H27-H6)/H6 -> #DIV/0!
A29: Dinner | F29: Dinner
A30: Greeter Total
A31: =A25 -> Non Meal Plan Meals
A32: =A26 -> Meal numbers
A33: Total - Dinner | B33: =SUM(B30:B32) -> 0 | C33: =SUM(C30:C32) -> 0 | D33: =SUM(D30:D32) -> 0 | E33: =SUM(E30:E32) -> 0 | F33: =SUM(F30:F32) -> 0 | G33: =SUM(G30:G32) -> 0 | H33: =SUM(H30:H32) -> 0
A34: % vPY Act | B34: =(B33-B7)/B7 -> #DIV/0! | C34: =(C33-C7)/C7 -> #DIV/0! | D34: =(D33-D7)/D7 -> #DIV/0! | E34: =(E33-E7)/E7 -> #DIV/0! | F34: =(F33-F7)/F7 -> #DIV/0! | G34: =(G33-G7)/G7 -> #DIV/0! | H34: =(H33-H7)/H7 -> #DIV/0!
A35: All Day | F35: Dinner
A36: Total - Day | B36: =B33+B27+B21 -> 0 | C36: =C33+C27+C21 -> 0 | D36: =D33+D27+D21 -> 0 | E36: =E33+E27+E21 -> 0 | F36: =F33+F27+F21 -> 0 | G36: =G33+G27+G21 -> 0 | H36: =H33+H27+H21 -> 0
A37: % vPY Act | B37: =(B36-B8)/B8 -> #DIV/0! | C37: =(C36-C8)/C8 -> #DIV/0! | D37: =(D36-D8)/D8 -> #DIV/0! | E37: =(E36-E8)/E8 -> #DIV/0! | F37: =(F36-F8)/F8 -> #DIV/0! | G37: =(G36-G8)/G8 -> #DIV/0! | H37: =(H36-H8)/H8 -> #DIV/0!
G38: Week Total | H38: =SUM(B36:H36) -> 0
G39: % vPY Act | H39: =(H38-H9)/H9 -> #DIV/0!
G40: % vForecast | H40: =(H38-H16)/H16 -> #DIV/0!
...

Sheet Week 9
E1: Menu Cycle: | G1: Week:
B2: Fri | C2: Sat | D2: Sun | E2: Mon | F2: Tue | G2: Wed | H2: Thu
A3: Date | B3: ='Week 8'!H3+1 -> 45949 | C3: =B3+1 -> 45950 | D3: =C3+1 -> 45951 | E3: =D3+1 -> 45952 | F3: =E3+1 -> 45953 | G3: =F3+1 -> 45954 | H3: =G3+1 -> 45955
A4: Prior Year Actual -2024
A5: Breakfast
A6: Lunch
A7: Dinner
A8: Total Day | B8: =B5+B6+B7 -> 0 | C8: =C5+C6+C7 -> 0 | D8: =D5+D6+D7 -> 0 | E8: =E5+E6+E7 -> 0 | F8: =F5+F6+F7 -> 0 | G8: =G5+G6+G7 -> 0 | H8: =H5+H6+H7 -> 0
G9: Week Total | H9: =SUM(B8:H8) -> 0
A10: Forecast - 2025 | G10: % Forecast Adj | H10: -0.15
A11: Breakfast
A12: Lunch
A13: Dinner
A14: Total Day | B14: =B11+B12+B13 -> 0 | C14: =C11+C12+C13 -> 0 | D14: =D11+D12+D13 -> 0 | E14: =E11+E12+E13 -> 0 | F14: =F11+F12+F13 -> 0 | G14: =G11+G12+G13 -> 0 | H14: =H11+H12+H13 -> 0
A15: % vPY Act | B15: =(B14-B8)/B8 -> #DIV/0! | C15: =(C14-C8)/C8 -> #DIV/0! | D15: =(D14-D8)/D8 -> #DIV/0! | E15: =(E14-E8)/E8 -> #DIV/0! | F15: =(F14-F8)/F8 -> #DIV/0! | G15: =(G14-G8)/G8 -> #DIV/0! | H15: =(H14-H8)/H8 -> #DIV/0!
G16: Week Total | H16: =SUM(B14:H14) -> 0
A17: Breakfast | G17: % vPY | H17: =(H16-H9)/H9 -> #DIV/0!
A18: Greeter Total
A19: ='Week 8'!A19 -> Non Meal Plan Meals
A20: ='Week 8'!A20 -> Meal numbers
A21: Total - Breakfast | B21: =SUM(B18:B20) -> 0 | C21: =SUM(C18:C20) -> 0 | D21: =SUM(D18:D20) -> 0 | E21: =SUM(E18:E20) -> 0 | F21: =SUM(F18:F20) -> 0 | G21: =SUM(G18:G20) -> 0 | H21: =SUM(H18:H20) -> 0
A22: % vPY Act | B22: =(B21-B5)/B5 -> #DIV/0! | C22: =(C21-C5)/C5 -> #DIV/0! | F22: =(F21-F5)/F5 -> #DIV/0! | G22: =(G21-G5)/G5 -> #DIV/0! | H22: =(H21-H5)/H5 -> #DIV/0!
A23: Lunch/Brunch | F23: Brunch/Lunch
A24: =A18 -> Greeter Total
A25: =A19 -> Non Meal Plan Meals
A26: =A20 -> Meal numbers
A27: Total - Lunch | B27: =SUM(B24:B26) -> 0 | C27: =SUM(C24:C26) -> 0 | D27: =SUM(D24:D26) -> 0 | E27: =SUM(E24:E26) -> 0 | F27: =SUM(F24:F26) -> 0 | G27: =SUM(G24:G26) -> 0 | H27: =SUM(H24:H26) -> 0
A28: % vPY Act | B28: =(B27-B6)/B6 -> #DIV/0! | C28: =(C27-C6)/C6 -> #DIV/0! | D28: =(D27-D6)/D6 -> #DIV/0! | E28: =(E27-E6)/E6 -> #DIV/0! | F28: =(F27-F6)/F6 -> #DIV/0! | G28: =(G27-G6)/G6 -> #DIV/0! | H28: =(H27-H6)/H6 -> #DIV/0!
A29: Dinner | F29: Dinner
A30: =A24 -> Greeter Total
A31: =A25 -> Non Meal Plan Meals
A32: =A26 -> Meal numbers
A33: Total - Dinner | B33: =SUM(B30:B32) -> 0 | C33: =SUM(C30:C32) -> 0 | D33: =SUM(D30:D32) -> 0 | E33: =SUM(E30:E32) -> 0 | F33: =SUM(F30:F32) -> 0 | G33: =SUM(G30:G32) -> 0 | H33: =SUM(H30:H32) -> 0
A34: % vPY Act | B34: =(B33-B7)/B7 -> #DIV/0! | C34: =(C33-C7)/C7 -> #DIV/0! | D34: =(D33-D7)/D7 -> #DIV/0! | E34: =(E33-E7)/E7 -> #DIV/0! | F34: =(F33-F7)/F7 -> #DIV/0! | G34: =(G33-G7)/G7 -> #DIV/0! | H34: =(H33-H7)/H7 -> #DIV/0!
A35: All Day | F35: Dinner
A36: Total - Day | B36: =B33+B27+B21 -> 0 | C36: =C33+C27+C21 -> 0 | D36: =D33+D27+D21 -> 0 | E36: =E33+E27+E21 -> 0 | F36: =F33+F27+F21 -> 0 | G36: =G33+G27+G21 -> 0 | H36: =H33+H27+H21 -> 0
A37: % vPY Act | B37: =(B36-B8)/B8 -> #DIV/0! | C37: =(C36-C8)/C8 -> #DIV/0! | D37: =(D36-D8)/D8 -> #DIV/0! | E37: =(E36-E8)/E8 -> #DIV/0! | F37: =(F36-F8)/F8 -> #DIV/0! | G37: =(G36-G8)/G8 -> #DIV/0! | H37: =(H36-H8)/H8 -> #DIV/0!
G38: Week Total | H38: =SUM(B36:H36) -> 0
G39: % vPY Act | H39: =(H38-H9)/H9 -> #DIV/0!
G40: % vForecast | H40: =(H38-H16)/H16 -> #DIV/0!
...

Sheet Average w6-9
E1: Menu Cycle: | G1: Week:
B2: Fri | C2: Sat | D2: Sun | E2: Mon | F2: Tue | G2: Wed | H2: Thu
A3: Date
A4: Prior Year Actual-2024
A5: Breakfast | B5: =('Week 9'!B5+'Week 8'!B5+'Week 7'!B5+'Week 6'!B5)/4 -> 0 | C5: =('Week 9'!C5+'Week 8'!C5+'Week 7'!C5+'Week 6'!C5)/4 -> 0 | D5: =('Week 9'!D5+'Week 8'!D5+'Week 7'!D5+'Week 6'!D5)/4 -> 0 | E5: =('Week 9'!E5+'Week 8'!E5+'Week 7'!E5+'Week 6'!E5)/4 -> 0 | F5: =('Week 9'!F5+'Week 8'!F5+'Week 7'!F5+'Week 6'!F5)/4 -> 0 | G5: =('Week 9'!G5+'Week 8'!G5+'Week 7'!G5+'Week 6'!G5)/4 -> 0 | H5: =('Week 9'!H5+'Week 8'!H5+'Week 7'!H5+'Week 6'!H5)/4 -> 0
A6: Lunch | B6: =('Week 9'!B6+'Week 8'!B6+'Week 7'!B6+'Week 6'!B6)/4 -> 0 | C6: =('Week 9'!C6+'Week 8'!C6+'Week 7'!C6+'Week 6'!C6)/4 -> 0 | D6: =('Week 9'!D6+'Week 8'!D6+'Week 7'!D6+'Week 6'!D6)/4 -> 0 | E6: =('Week 9'!E6+'Week 8'!E6+'Week 7'!E6+'Week 6'!E6)/4 -> 0 | F6: =('Week 9'!F6+'Week 8'!F6+'Week 7'!F6+'Week 6'!F6)/4 -> 0 | G6: =('Week 9'!G6+'Week 8'!G6+'Week 7'!G6+'Week 6'!G6)/4 -> 0 | H6: =('Week 9'!H6+'Week 8'!H6+'Week 7'!H6+'Week 6'!H6)/4 -> 0
A7: Dinner | B7: =('Week 9'!B7+'Week 8'!B7+'Week 7'!B7+'Week 6'!B7)/4 -> 0 | C7: =('Week 9'!C7+'Week 8'!C7+'Week 7'!C7+'Week 6'!C7)/4 -> 0 | D7: =('Week 9'!D7+'Week 8'!D7+'Week 7'!D7+'Week 6'!D7)/4 -> 0 | E7: =('Week 9'!E7+'Week 8'!E7+'Week 7'!E7+'Week 6'!E7)/4 -> 0 | F7: =('Week 9'!F7+'Week 8'!F7+'Week 7'!F7+'Week 6'!F7)/4 -> 0 | G7: =('Week 9'!G7+'Week 8'!G7+'Week 7'!G7+'Week 6'!G7)/4 -> 0 | H7: =('Week 9'!H7+'Week 8'!H7+'Week 7'!H7+'Week 6'!H7)/4 -> 0
A8: Total Day | B8: =B5+B6+B7 -> 0 | C8: =C5+C6+C7 -> 0 | D8: =D5+D6+D7 -> 0 | E8: =E5+E6+E7 -> 0 | F8: =F5+F6+F7 -> 0 | G8: =G5+G6+G7 -> 0 | H8: =H5+H6+H7 -> 0
G9: Week Total | H9: =SUM(B8:H8) -> 0
A10: Forecast-2025 | G10: % Forecast Adj | H10: 0
A11: Breakfast | B11: =('Week 9'!B11+'Week 8'!B11+'Week 7'!B11+'Week 6'!B11)/4 -> 0 | C11: =('Week 9'!C11+'Week 8'!C11+'Week 7'!C11+'Week 6'!C11)/4 -> 0 | D11: =('Week 9'!D11+'Week 8'!D11+'Week 7'!D11+'Week 6'!D11)/4 -> 0 | E11: =('Week 9'!E11+'Week 8'!E11+'Week 7'!E11+'Week 6'!E11)/4 -> 0 | F11: =('Week 9'!F11+'Week 8'!F11+'Week 7'!F11+'Week 6'!F11)/4 -> 0 | G11: =('Week 9'!G11+'Week 8'!G11+'Week 7'!G11+'Week 6'!G11)/4 -> 0 | H11: =('Week 9'!H11+'Week 8'!H11+'Week 7'!H11+'Week 6'!H11)/4 -> 0
A12: Lunch | B12: =('Week 9'!B12+'Week 8'!B12+'Week 7'!B12+'Week 6'!B12)/4 -> 0 | C12: =('Week 9'!C12+'Week 8'!C12+'Week 7'!C12+'Week 6'!C12)/4 -> 0 | D12: =('Week 9'!D12+'Week 8'!D12+'Week 7'!D12+'Week 6'!D12)/4 -> 0 | E12: =('Week 9'!E12+'Week 8'!E12+'Week 7'!E12+'Week 6'!E12)/4 -> 0 | F12: =('Week 9'!F12+'Week 8'!F12+'Week 7'!F12+'Week 6'!F12)/4 -> 0 | G12: =('Week 9'!G12+'Week 8'!G12+'Week 7'!G12+'Week 6'!G12)/4 -> 0 | H12: =('Week 9'!H12+'Week 8'!H12+'Week 7'!H12+'Week 6'!H12)/4 -> 0
A13: Dinner | B13: =('Week 9'!B13+'Week 8'!B13+'Week 7'!B13+'Week 6'!B13)/4 -> 0 | C13: =('Week 9'!C13+'Week 8'!C13+'Week 7'!C13+'Week 6'!C13)/4 -> 0 | D13: =('Week 9'!D13+'Week 8'!D13+'Week 7'!D13+'Week 6'!D13)/4 -> 0 | E13: =('Week 9'!E13+'Week 8'!E13+'Week 7'!E13+'Week 6'!E13)/4 -> 0 | F13: =('Week 9'!F13+'Week 8'!F13+'Week 7'!F13+'Week 6'!F13)/4 -> 0 | G13: =('Week 9'!G13+'Week 8'!G13+'Week 7'!G13+'Week 6'!G13)/4 -> 0 | H13: =('Week 9'!H13+'Week 8'!H13+'Week 7'!H13+'Week 6'!H13)/4 -> 0
A14: Total Day | B14: =B11+B12+B13 -> 0 | C14: =C11+C12+C13 -> 0 | D14: =D11+D12+D13 -> 0 | E14: =E11+E12+E13 -> 0 | F14: =F11+F12+F13 -> 0 | G14: =G11+G12+G13 -> 0 | H14: =H11+H12+H13 -> 0
A15: % vPY Act | B15: =(B14-B8)/B8 -> #DIV/0! | C15: =(C14-C8)/C8 -> #DIV/0! | D15: =(D14-D8)/D8 -> #DIV/0! | E15: =(E14-E8)/E8 -> #DIV/0! | F15: =(F14-F8)/F8 -> #DIV/0! | G15: =(G14-G8)/G8 -> #DIV/0! | H15: =(H14-H8)/H8 -> #DIV/0!
G16: Week Total | H16: =SUM(B14:H14) -> 0
A17: Breakfast | G17: % vPY | H17: =(H16-H9)/H9 -> #DIV/0!
A18: Greeter Total
A19: ='Week 9'!A25 -> Non Meal Plan Meals
A20: ='Week 9'!A26 -> Meal numbers
A21: Total - Breakfast | B21: =('Week 9'!B21+'Week 8'!B21+'Week 7'!B21+'Week 6'!B21)/4 -> 0 | C21: =('Week 9'!C21+'Week 8'!C21+'Week 7'!C21+'Week 6'!C21)/4 -> 65.5 | D21: =('Week 9'!D21+'Week 8'!D21+'Week 7'!D21+'Week 6'!D21)/4 -> 0 | E21: =('Week 9'!E21+'Week 8'!E21+'Week 7'!E21+'Week 6'!E21)/4 -> 0 | F21: =('Week 9'!F21+'Week 8'!F21+'Week 7'!F21+'Week 6'!F21)/4 -> 0 | G21: =('Week 9'!G21+'Week 8'!G21+'Week 7'!G21+'Week 6'!G21)/4 -> 0 | H21: =('Week 9'!H21+'Week 8'!H21+'Week 7'!H21+'Week 6'!H21)/4 -> 0
A22: % vPY Act | B22: =(B21-B5)/B5 -> #DIV/0! | C22: =(C21-C5)/C5 -> #DIV/0! | F22: =(F21-F5)/F5 -> #DIV/0! | G22: =(G21-G5)/G5 -> #DIV/0! | H22: =(H21-H5)/H5 -> #DIV/0!
A23: Lunch/Brunch | F23: Brunch/Lunch
A24: Greeter Total
A25: =A19 -> Non Meal Plan Meals
A26: =A20 -> Meal numbers
A27: Total - Lunch | B27: =('Week 9'!B27+'Week 8'!B27+'Week 7'!B28+'Week 6'!B27)/4 -> 78.25 | C27: =('Week 9'!C27+'Week 8'!C27+'Week 7'!C28+'Week 6'!C27)/4 -> 164.5 | D27: =('Week 9'!D27+'Week 8'!D27+'Week 7'!D28+'Week 6'!D27)/4 -> 0 | E27: =('Week 9'!E27+'Week 8'!E27+'Week 7'!E28+'Week 6'!E27)/4 -> 0 | F27: =('Week 9'!F27+'Week 8'!F27+'Week 7'!F28+'Week 6'!F27)/4 -> 0 | G27: =('Week 9'!G27+'Week 8'!G27+'Week 7'!G28+'Week 6'!G27)/4 -> 0 | H27: =('Week 9'!H27+'Week 8'!H27+'Week 7'!H28+'Week 6'!H27)/4 -> 0
A28: % vPY Act | B28: =(B27-B6)/B6 -> #DIV/0! | C28: =(C27-C6)/C6 -> #DIV/0! | D28: =(D27-D6)/D6 -> #DIV/0! | E28: =(E27-E6)/E6 -> #DIV/0! | F28: =(F27-F6)/F6 -> #DIV/0! | G28: =(G27-G6)/G6 -> #DIV/0! | H28: =(H27-H6)/H6 -> #DIV/0!
A29: Dinner | F29: Dinner
A30: Greeter Total
A31: =A25 -> Non Meal Plan Meals
A32: =A26 -> Meal numbers
A33: Total - Dinner | B33: =('Week 9'!B33+'Week 8'!B33+'Week 7'!B34+'Week 6'!B33)/4 -> 70.75 | C33: =('Week 9'!C33+'Week 8'!C33+'Week 7'!C34+'Week 6'!C33)/4 -> 156.75 | D33: =('Week 9'!D33+'Week 8'!D33+'Week 7'!D34+'Week 6'!D33)/4 -> 0 | E33: =('Week 9'!E33+'Week 8'!E33+'Week 7'!E34+'Week 6'!E33)/4 -> 0 | F33: =('Week 9'!F33+'Week 8'!F33+'Week 7'!F34+'Week 6'!F33)/4 -> 0 | G33: =('Week 9'!G33+'Week 8'!G33+'Week 7'!G34+'Week 6'!G33)/4 -> 0 | H33: =('Week 9'!H33+'Week 8'!H33+'Week 7'!H34+'Week 6'!H33)/4 -> 0
A34: % vPY Act | B34: =(B33-B7)/B7 -> #DIV/0! | C34: =(C33-C7)/C7 -> #DIV/0! | D34: =(D33-D7)/D7 -> #DIV/0! | E34: =(E33-E7)/E7 -> #DIV/0! | F34: =(F33-F7)/F7 -> #DIV/0! | G34: =(G33-G7)/G7 -> #DIV/0! | H34: =(H33-H7)/H7 -> #DIV/0!
A35: All Day | F35: Dinner
A36: Total - Day | B36: =('Week 9'!B36+'Week 8'!B36+'Week 7'!B37+'Week 6'!B36)/4 -> 149 | C36: =('Week 9'!C36+'Week 8'!C36+'Week 7'!C37+'Week 6'!C36)/4 -> 386.75 | D36: =('Week 9'!D36+'Week 8'!D36+'Week 7'!D37+'Week 6'!D36)/4 -> 0 | E36: =('Week 9'!E36+'Week 8'!E36+'Week 7'!E37+'Week 6'!E36)/4 -> 0 | F36: =('Week 9'!F36+'Week 8'!F36+'Week 7'!F37+'Week 6'!F36)/4 -> 0 | G36: =('Week 9'!G36+'Week 8'!G36+'Week 7'!G37+'Week 6'!G36)/4 -> 0 | H36: =('Week 9'!H36+'Week 8'!H36+'Week 7'!H37+'Week 6'!H36)/4 -> 0
